[2024-04-08T10:38:16.450+0000] {taskinstance.py:1956} INFO - Dependencies all met for dep_context=non-requeueable deps ti=<TaskInstance: dag___dbt.run_model1 scheduled__2024-04-07T10:00:00+00:00 [queued]>
[2024-04-08T10:38:16.463+0000] {taskinstance.py:1956} INFO - Dependencies all met for dep_context=requeueable deps ti=<TaskInstance: dag___dbt.run_model1 scheduled__2024-04-07T10:00:00+00:00 [queued]>
[2024-04-08T10:38:16.464+0000] {taskinstance.py:2170} INFO - Starting attempt 2 of 2
[2024-04-08T10:38:16.489+0000] {taskinstance.py:2191} INFO - Executing <Task(BashOperator): run_model1> on 2024-04-07 10:00:00+00:00
[2024-04-08T10:38:16.499+0000] {standard_task_runner.py:60} INFO - Started process 273 to run task
[2024-04-08T10:38:16.505+0000] {standard_task_runner.py:87} INFO - Running: ['***', 'tasks', 'run', 'dag___dbt', 'run_model1', 'scheduled__2024-04-07T10:00:00+00:00', '--job-id', '436', '--raw', '--subdir', 'DAGS_FOLDER/freshness_test_dag.py', '--cfg-path', '/tmp/tmp_ti0s8ut']
[2024-04-08T10:38:16.512+0000] {standard_task_runner.py:88} INFO - Job 436: Subtask run_model1
[2024-04-08T10:38:16.626+0000] {task_command.py:423} INFO - Running <TaskInstance: dag___dbt.run_model1 scheduled__2024-04-07T10:00:00+00:00 [running]> on host 62dc842f1ceb
[2024-04-08T10:38:16.823+0000] {taskinstance.py:2480} INFO - Exporting env vars: AIRFLOW_CTX_DAG_OWNER='***' AIRFLOW_CTX_DAG_ID='dag___dbt' AIRFLOW_CTX_TASK_ID='run_model1' AIRFLOW_CTX_EXECUTION_DATE='2024-04-07T10:00:00+00:00' AIRFLOW_CTX_TRY_NUMBER='2' AIRFLOW_CTX_DAG_RUN_ID='scheduled__2024-04-07T10:00:00+00:00'
[2024-04-08T10:38:16.826+0000] {subprocess.py:63} INFO - Tmp dir root location: /tmp
[2024-04-08T10:38:16.828+0000] {subprocess.py:75} INFO - Running command: ['/usr/bin/bash', '-c', '/home/***/.local/bin/dbt run --models my_first_dbt_model my_second_dbt_model  --profiles-dir /home/***/.dbt --project-dir /opt/***/proj']
[2024-04-08T10:38:16.849+0000] {subprocess.py:86} INFO - Output:
[2024-04-08T10:38:23.177+0000] {subprocess.py:93} INFO - [0m10:38:23  Running with dbt=1.7.10
[2024-04-08T10:38:24.024+0000] {subprocess.py:93} INFO - [0m10:38:24  Registered adapter: postgres=1.7.10
[2024-04-08T10:38:34.926+0000] {subprocess.py:93} INFO - [0m10:38:34  Found 34 models, 2 operations, 6 tests, 1 source, 0 exposures, 0 metrics, 1407 macros, 0 groups, 0 semantic models
[2024-04-08T10:38:34.946+0000] {subprocess.py:93} INFO - [0m10:38:34
[2024-04-08T10:38:36.027+0000] {subprocess.py:93} INFO - [0m10:38:36
[2024-04-08T10:38:36.030+0000] {subprocess.py:93} INFO - [0m10:38:36  Running 1 on-run-start hook
[2024-04-08T10:38:36.178+0000] {subprocess.py:93} INFO - [0m10:38:36  1 of 1 START hook: elementary.on-run-start.0 ................................... [RUN]
[2024-04-08T10:38:36.180+0000] {subprocess.py:93} INFO - [0m10:38:36  1 of 1 OK hook: elementary.on-run-start.0 ...................................... [[32mOK[0m in 0.00s]
[2024-04-08T10:38:36.182+0000] {subprocess.py:93} INFO - [0m10:38:36
[2024-04-08T10:38:36.189+0000] {subprocess.py:93} INFO - [0m10:38:36  Concurrency: 1 threads (target='dev')
[2024-04-08T10:38:36.194+0000] {subprocess.py:93} INFO - [0m10:38:36
[2024-04-08T10:38:36.218+0000] {subprocess.py:93} INFO - [0m10:38:36  1 of 2 START sql table model public.my_first_dbt_model ......................... [RUN]
[2024-04-08T10:38:36.719+0000] {subprocess.py:93} INFO - [0m10:38:36  1 of 2 ERROR creating sql table model public.my_first_dbt_model ................ [[31mERROR[0m in 0.50s]
[2024-04-08T10:38:36.728+0000] {subprocess.py:93} INFO - [0m10:38:36  2 of 2 SKIP relation public.my_second_dbt_model ................................ [[33mSKIP[0m]
[2024-04-08T10:38:36.896+0000] {subprocess.py:93} INFO - [0m10:38:36
[2024-04-08T10:38:36.904+0000] {subprocess.py:93} INFO - [0m10:38:36  Running 1 on-run-end hook
[2024-04-08T10:38:42.582+0000] {subprocess.py:93} INFO - [0m10:38:42  1 of 1 START hook: elementary.on-run-end.0 ..................................... [RUN]
[2024-04-08T10:38:42.588+0000] {subprocess.py:93} INFO - [0m10:38:42  1 of 1 OK hook: elementary.on-run-end.0 ........................................ [[32mOK[0m in 0.00s]
[2024-04-08T10:38:42.599+0000] {subprocess.py:93} INFO - [0m10:38:42
[2024-04-08T10:38:42.621+0000] {subprocess.py:93} INFO - [0m10:38:42
[2024-04-08T10:38:42.630+0000] {subprocess.py:93} INFO - [0m10:38:42  Finished running 1 table model, 1 view model, 2 hooks in 0 hours 0 minutes and 7.67 seconds (7.67s).
[2024-04-08T10:38:42.830+0000] {subprocess.py:93} INFO - [0m10:38:42
[2024-04-08T10:38:42.833+0000] {subprocess.py:93} INFO - [0m10:38:42  [31mCompleted with 1 error and 0 warnings:[0m
[2024-04-08T10:38:42.838+0000] {subprocess.py:93} INFO - [0m10:38:42
[2024-04-08T10:38:42.842+0000] {subprocess.py:93} INFO - [0m10:38:42    Database Error in model my_first_dbt_model (models/example/my_first_dbt_model.sql)
[2024-04-08T10:38:42.844+0000] {subprocess.py:93} INFO -   ERREUR:  la relation Â« my_first_dbt_model__dbt_backup Â» existe dÃ©jÃ 
[2024-04-08T10:38:42.845+0000] {subprocess.py:93} INFO -   compiled Code at target/run/proj/models/example/my_first_dbt_model.sql
[2024-04-08T10:38:42.847+0000] {subprocess.py:93} INFO - [0m10:38:42
[2024-04-08T10:38:42.853+0000] {subprocess.py:93} INFO - [0m10:38:42  Done. PASS=0 WARN=0 ERROR=1 SKIP=1 TOTAL=2
[2024-04-08T10:38:46.399+0000] {subprocess.py:97} INFO - Command exited with return code 1
[2024-04-08T10:38:46.470+0000] {taskinstance.py:2698} ERROR - Task failed with exception
Traceback (most recent call last):
  File "/home/airflow/.local/lib/python3.8/site-packages/airflow/models/taskinstance.py", line 433, in _execute_task
    result = execute_callable(context=context, **execute_callable_kwargs)
  File "/home/airflow/.local/lib/python3.8/site-packages/airflow/operators/bash.py", line 212, in execute
    raise AirflowException(
airflow.exceptions.AirflowException: Bash command failed. The command returned a non-zero exit code 1.
[2024-04-08T10:38:46.491+0000] {taskinstance.py:1138} INFO - Marking task as FAILED. dag_id=dag___dbt, task_id=run_model1, execution_date=20240407T100000, start_date=20240408T103816, end_date=20240408T103846
[2024-04-08T10:38:46.594+0000] {standard_task_runner.py:107} ERROR - Failed to execute job 436 for task run_model1 (Bash command failed. The command returned a non-zero exit code 1.; 273)
[2024-04-08T10:38:46.637+0000] {local_task_job_runner.py:234} INFO - Task exited with return code 1
[2024-04-08T10:38:46.703+0000] {taskinstance.py:3280} INFO - 0 downstream tasks scheduled from follow-on schedule check
