[2024-04-08T10:31:21.594+0000] {taskinstance.py:1956} INFO - Dependencies all met for dep_context=non-requeueable deps ti=<TaskInstance: dag___dbt.run_model1 scheduled__2024-04-07T10:00:00+00:00 [queued]>
[2024-04-08T10:31:21.723+0000] {taskinstance.py:1956} INFO - Dependencies all met for dep_context=requeueable deps ti=<TaskInstance: dag___dbt.run_model1 scheduled__2024-04-07T10:00:00+00:00 [queued]>
[2024-04-08T10:31:21.726+0000] {taskinstance.py:2170} INFO - Starting attempt 1 of 2
[2024-04-08T10:31:21.975+0000] {taskinstance.py:2191} INFO - Executing <Task(BashOperator): run_model1> on 2024-04-07 10:00:00+00:00
[2024-04-08T10:31:22.126+0000] {standard_task_runner.py:60} INFO - Started process 78 to run task
[2024-04-08T10:31:22.143+0000] {standard_task_runner.py:87} INFO - Running: ['***', 'tasks', 'run', 'dag___dbt', 'run_model1', 'scheduled__2024-04-07T10:00:00+00:00', '--job-id', '426', '--raw', '--subdir', 'DAGS_FOLDER/freshness_test_dag.py', '--cfg-path', '/tmp/tmpox3upkr4']
[2024-04-08T10:31:22.257+0000] {standard_task_runner.py:88} INFO - Job 426: Subtask run_model1
[2024-04-08T10:31:23.304+0000] {task_command.py:423} INFO - Running <TaskInstance: dag___dbt.run_model1 scheduled__2024-04-07T10:00:00+00:00 [running]> on host 62dc842f1ceb
[2024-04-08T10:31:24.213+0000] {taskinstance.py:2480} INFO - Exporting env vars: AIRFLOW_CTX_DAG_OWNER='***' AIRFLOW_CTX_DAG_ID='dag___dbt' AIRFLOW_CTX_TASK_ID='run_model1' AIRFLOW_CTX_EXECUTION_DATE='2024-04-07T10:00:00+00:00' AIRFLOW_CTX_TRY_NUMBER='1' AIRFLOW_CTX_DAG_RUN_ID='scheduled__2024-04-07T10:00:00+00:00'
[2024-04-08T10:31:24.244+0000] {subprocess.py:63} INFO - Tmp dir root location: /tmp
[2024-04-08T10:31:24.266+0000] {subprocess.py:75} INFO - Running command: ['/usr/bin/bash', '-c', '/home/***/.local/bin/dbt run --models my_first_dbt_model my_second_dbt_model  --profiles-dir /home/***/.dbt --project-dir /opt/***/proj']
[2024-04-08T10:31:24.321+0000] {subprocess.py:86} INFO - Output:
[2024-04-08T10:32:15.932+0000] {subprocess.py:93} INFO - [0m10:32:15  Running with dbt=1.7.10
[2024-04-08T10:32:21.842+0000] {subprocess.py:93} INFO - [0m10:32:21  Registered adapter: postgres=1.7.10
[2024-04-08T10:32:43.369+0000] {subprocess.py:93} INFO - [0m10:32:43  Found 34 models, 2 operations, 6 tests, 1 source, 0 exposures, 0 metrics, 1407 macros, 0 groups, 0 semantic models
[2024-04-08T10:32:43.493+0000] {subprocess.py:93} INFO - [0m10:32:43
[2024-04-08T10:32:48.071+0000] {subprocess.py:93} INFO - [0m10:32:48
[2024-04-08T10:32:48.076+0000] {subprocess.py:93} INFO - [0m10:32:48  Running 1 on-run-start hook
[2024-04-08T10:32:48.870+0000] {subprocess.py:93} INFO - [0m10:32:48  1 of 1 START hook: elementary.on-run-start.0 ................................... [RUN]
[2024-04-08T10:32:48.940+0000] {subprocess.py:93} INFO - [0m10:32:48  1 of 1 OK hook: elementary.on-run-start.0 ...................................... [[32mOK[0m in 0.00s]
[2024-04-08T10:32:49.011+0000] {subprocess.py:93} INFO - [0m10:32:49
[2024-04-08T10:32:49.032+0000] {subprocess.py:93} INFO - [0m10:32:49  Concurrency: 1 threads (target='dev')
[2024-04-08T10:32:49.049+0000] {subprocess.py:93} INFO - [0m10:32:49
[2024-04-08T10:32:49.483+0000] {subprocess.py:93} INFO - [0m10:32:49  1 of 2 START sql table model public.my_first_dbt_model ......................... [RUN]
[2024-04-08T10:32:53.051+0000] {subprocess.py:93} INFO - [0m10:32:53  1 of 2 ERROR creating sql table model public.my_first_dbt_model ................ [[31mERROR[0m in 3.53s]
[2024-04-08T10:32:53.087+0000] {subprocess.py:93} INFO - [0m10:32:53  2 of 2 SKIP relation public.my_second_dbt_model ................................ [[33mSKIP[0m]
[2024-04-08T10:32:53.514+0000] {subprocess.py:93} INFO - [0m10:32:53
[2024-04-08T10:32:53.537+0000] {subprocess.py:93} INFO - [0m10:32:53  Running 1 on-run-end hook
[2024-04-08T10:33:10.634+0000] {subprocess.py:93} INFO - [0m10:33:10  1 of 1 START hook: elementary.on-run-end.0 ..................................... [RUN]
[2024-04-08T10:33:10.638+0000] {subprocess.py:93} INFO - [0m10:33:10  1 of 1 OK hook: elementary.on-run-end.0 ........................................ [[32mOK[0m in 0.00s]
[2024-04-08T10:33:10.644+0000] {subprocess.py:93} INFO - [0m10:33:10
[2024-04-08T10:33:10.689+0000] {subprocess.py:93} INFO - [0m10:33:10
[2024-04-08T10:33:10.695+0000] {subprocess.py:93} INFO - [0m10:33:10  Finished running 1 table model, 1 view model, 2 hooks in 0 hours 0 minutes and 27.16 seconds (27.16s).
[2024-04-08T10:33:10.976+0000] {subprocess.py:93} INFO - [0m10:33:10
[2024-04-08T10:33:10.986+0000] {subprocess.py:93} INFO - [0m10:33:10  [31mCompleted with 1 error and 0 warnings:[0m
[2024-04-08T10:33:10.990+0000] {subprocess.py:93} INFO - [0m10:33:10
[2024-04-08T10:33:10.996+0000] {subprocess.py:93} INFO - [0m10:33:10    Database Error in model my_first_dbt_model (models/example/my_first_dbt_model.sql)
[2024-04-08T10:33:11.006+0000] {subprocess.py:93} INFO -   ERREUR:  la relation Â« my_first_dbt_model__dbt_backup Â» existe dÃ©jÃ 
[2024-04-08T10:33:11.012+0000] {subprocess.py:93} INFO -   compiled Code at target/run/proj/models/example/my_first_dbt_model.sql
[2024-04-08T10:33:11.018+0000] {subprocess.py:93} INFO - [0m10:33:11
[2024-04-08T10:33:11.026+0000] {subprocess.py:93} INFO - [0m10:33:11  Done. PASS=0 WARN=0 ERROR=1 SKIP=1 TOTAL=2
[2024-04-08T10:33:12.885+0000] {subprocess.py:97} INFO - Command exited with return code 1
[2024-04-08T10:33:12.939+0000] {taskinstance.py:2698} ERROR - Task failed with exception
Traceback (most recent call last):
  File "/home/airflow/.local/lib/python3.8/site-packages/airflow/models/taskinstance.py", line 433, in _execute_task
    result = execute_callable(context=context, **execute_callable_kwargs)
  File "/home/airflow/.local/lib/python3.8/site-packages/airflow/operators/bash.py", line 212, in execute
    raise AirflowException(
airflow.exceptions.AirflowException: Bash command failed. The command returned a non-zero exit code 1.
[2024-04-08T10:33:13.003+0000] {taskinstance.py:1138} INFO - Marking task as UP_FOR_RETRY. dag_id=dag___dbt, task_id=run_model1, execution_date=20240407T100000, start_date=20240408T103121, end_date=20240408T103313
[2024-04-08T10:33:13.064+0000] {standard_task_runner.py:107} ERROR - Failed to execute job 426 for task run_model1 (Bash command failed. The command returned a non-zero exit code 1.; 78)
[2024-04-08T10:33:13.118+0000] {local_task_job_runner.py:234} INFO - Task exited with return code 1
[2024-04-08T10:33:13.220+0000] {taskinstance.py:3280} INFO - 0 downstream tasks scheduled from follow-on schedule check
