[2024-04-01T12:29:21.425+0000] {taskinstance.py:1956} INFO - Dependencies all met for dep_context=non-requeueable deps ti=<TaskInstance: dag___fresh.extract_dbt_result_task manual__2024-04-01T12:28:52.427727+00:00 [queued]>
[2024-04-01T12:29:21.441+0000] {taskinstance.py:1956} INFO - Dependencies all met for dep_context=requeueable deps ti=<TaskInstance: dag___fresh.extract_dbt_result_task manual__2024-04-01T12:28:52.427727+00:00 [queued]>
[2024-04-01T12:29:21.442+0000] {taskinstance.py:2170} INFO - Starting attempt 1 of 2
[2024-04-01T12:29:21.466+0000] {taskinstance.py:2191} INFO - Executing <Task(PythonOperator): extract_dbt_result_task> on 2024-04-01 12:28:52.427727+00:00
[2024-04-01T12:29:21.477+0000] {standard_task_runner.py:60} INFO - Started process 2904 to run task
[2024-04-01T12:29:21.482+0000] {standard_task_runner.py:87} INFO - Running: ['***', 'tasks', 'run', 'dag___fresh', 'extract_dbt_result_task', 'manual__2024-04-01T12:28:52.427727+00:00', '--job-id', '328', '--raw', '--subdir', 'DAGS_FOLDER/dbt_dag.py', '--cfg-path', '/tmp/tmp5glv60hk']
[2024-04-01T12:29:21.488+0000] {standard_task_runner.py:88} INFO - Job 328: Subtask extract_dbt_result_task
[2024-04-01T12:29:21.566+0000] {task_command.py:423} INFO - Running <TaskInstance: dag___fresh.extract_dbt_result_task manual__2024-04-01T12:28:52.427727+00:00 [running]> on host 62dc842f1ceb
[2024-04-01T12:29:21.714+0000] {taskinstance.py:2480} INFO - Exporting env vars: AIRFLOW_CTX_DAG_OWNER='***' AIRFLOW_CTX_DAG_ID='dag___fresh' AIRFLOW_CTX_TASK_ID='extract_dbt_result_task' AIRFLOW_CTX_EXECUTION_DATE='2024-04-01T12:28:52.427727+00:00' AIRFLOW_CTX_TRY_NUMBER='1' AIRFLOW_CTX_DAG_RUN_ID='manual__2024-04-01T12:28:52.427727+00:00'
[2024-04-01T12:29:21.717+0000] {taskinstance.py:2698} ERROR - Task failed with exception
Traceback (most recent call last):
  File "/home/airflow/.local/lib/python3.8/site-packages/airflow/models/taskinstance.py", line 433, in _execute_task
    result = execute_callable(context=context, **execute_callable_kwargs)
  File "/home/airflow/.local/lib/python3.8/site-packages/airflow/operators/python.py", line 199, in execute
    return_value = self.execute_callable()
  File "/home/airflow/.local/lib/python3.8/site-packages/airflow/operators/python.py", line 216, in execute_callable
    return self.python_callable(*self.op_args, **self.op_kwargs)
  File "/opt/airflow/dags/dbt_dag.py", line 28, in extract_and_set_dbt_result
    logs = ti.logs
AttributeError: 'TaskInstance' object has no attribute 'logs'
[2024-04-01T12:29:21.735+0000] {taskinstance.py:1138} INFO - Marking task as UP_FOR_RETRY. dag_id=dag___fresh, task_id=extract_dbt_result_task, execution_date=20240401T122852, start_date=20240401T122921, end_date=20240401T122921
[2024-04-01T12:29:21.754+0000] {standard_task_runner.py:107} ERROR - Failed to execute job 328 for task extract_dbt_result_task ('TaskInstance' object has no attribute 'logs'; 2904)
[2024-04-01T12:29:21.775+0000] {local_task_job_runner.py:234} INFO - Task exited with return code 1
[2024-04-01T12:29:21.838+0000] {taskinstance.py:3280} INFO - 0 downstream tasks scheduled from follow-on schedule check
