[2024-04-01T10:36:12.713+0000] {taskinstance.py:1956} INFO - Dependencies all met for dep_context=non-requeueable deps ti=<TaskInstance: dag___fresness.run_model1 scheduled__2024-03-15T00:00:00+00:00 [queued]>
[2024-04-01T10:36:12.747+0000] {taskinstance.py:1956} INFO - Dependencies all met for dep_context=requeueable deps ti=<TaskInstance: dag___fresness.run_model1 scheduled__2024-03-15T00:00:00+00:00 [queued]>
[2024-04-01T10:36:12.749+0000] {taskinstance.py:2170} INFO - Starting attempt 1 of 2
[2024-04-01T10:36:12.874+0000] {taskinstance.py:2191} INFO - Executing <Task(BashOperator): run_model1> on 2024-03-15 00:00:00+00:00
[2024-04-01T10:36:12.902+0000] {standard_task_runner.py:60} INFO - Started process 486 to run task
[2024-04-01T10:36:12.950+0000] {standard_task_runner.py:87} INFO - Running: ['***', 'tasks', 'run', 'dag___fresness', 'run_model1', 'scheduled__2024-03-15T00:00:00+00:00', '--job-id', '244', '--raw', '--subdir', 'DAGS_FOLDER/dbt_dag.py', '--cfg-path', '/tmp/tmpt_i8k2_3']
[2024-04-01T10:36:12.966+0000] {standard_task_runner.py:88} INFO - Job 244: Subtask run_model1
[2024-04-01T10:36:13.274+0000] {task_command.py:423} INFO - Running <TaskInstance: dag___fresness.run_model1 scheduled__2024-03-15T00:00:00+00:00 [running]> on host 62dc842f1ceb
[2024-04-01T10:36:13.739+0000] {taskinstance.py:2480} INFO - Exporting env vars: AIRFLOW_CTX_DAG_OWNER='***' AIRFLOW_CTX_DAG_ID='dag___fresness' AIRFLOW_CTX_TASK_ID='run_model1' AIRFLOW_CTX_EXECUTION_DATE='2024-03-15T00:00:00+00:00' AIRFLOW_CTX_TRY_NUMBER='1' AIRFLOW_CTX_DAG_RUN_ID='scheduled__2024-03-15T00:00:00+00:00'
[2024-04-01T10:36:13.747+0000] {subprocess.py:63} INFO - Tmp dir root location: /tmp
[2024-04-01T10:36:13.750+0000] {subprocess.py:75} INFO - Running command: ['/usr/bin/bash', '-c', '/home/***/.local/bin/dbt run --models  --profiles-dir /home/***/.dbt --project-dir /opt/***/proj']
[2024-04-01T10:36:13.879+0000] {subprocess.py:86} INFO - Output:
[2024-04-01T10:36:55.130+0000] {subprocess.py:93} INFO - [0m10:36:55  Running with dbt=1.7.10
[2024-04-01T10:36:56.006+0000] {subprocess.py:93} INFO - [0m10:36:56  Encountered an error:
[2024-04-01T10:36:56.007+0000] {subprocess.py:93} INFO - [Errno 5] Input/output error: '/opt/***/proj/dbt_project.yml'
[2024-04-01T10:36:56.025+0000] {subprocess.py:93} INFO - [0m10:36:56  Traceback (most recent call last):
[2024-04-01T10:36:56.026+0000] {subprocess.py:93} INFO -   File "/home/***/.local/lib/python3.8/site-packages/dbt/cli/requires.py", line 91, in wrapper
[2024-04-01T10:36:56.027+0000] {subprocess.py:93} INFO -     result, success = func(*args, **kwargs)
[2024-04-01T10:36:56.028+0000] {subprocess.py:93} INFO -   File "/home/***/.local/lib/python3.8/site-packages/dbt/cli/requires.py", line 76, in wrapper
[2024-04-01T10:36:56.029+0000] {subprocess.py:93} INFO -     return func(*args, **kwargs)
[2024-04-01T10:36:56.030+0000] {subprocess.py:93} INFO -   File "/home/***/.local/lib/python3.8/site-packages/dbt/cli/requires.py", line 169, in wrapper
[2024-04-01T10:36:56.031+0000] {subprocess.py:93} INFO -     return func(*args, **kwargs)
[2024-04-01T10:36:56.032+0000] {subprocess.py:93} INFO -   File "/home/***/.local/lib/python3.8/site-packages/dbt/cli/requires.py", line 185, in wrapper
[2024-04-01T10:36:56.032+0000] {subprocess.py:93} INFO -     project = load_project(
[2024-04-01T10:36:56.033+0000] {subprocess.py:93} INFO -   File "/home/***/.local/lib/python3.8/site-packages/dbt/config/runtime.py", line 50, in load_project
[2024-04-01T10:36:56.035+0000] {subprocess.py:93} INFO -     project = Project.from_project_root(
[2024-04-01T10:36:56.036+0000] {subprocess.py:93} INFO -   File "/home/***/.local/lib/python3.8/site-packages/dbt/config/project.py", line 742, in from_project_root
[2024-04-01T10:36:56.037+0000] {subprocess.py:93} INFO -     partial = PartialProject.from_project_root(project_root, verify_version=verify_version)
[2024-04-01T10:36:56.038+0000] {subprocess.py:93} INFO -   File "/home/***/.local/lib/python3.8/site-packages/dbt/config/project.py", line 565, in from_project_root
[2024-04-01T10:36:56.039+0000] {subprocess.py:93} INFO -     project_dict = load_raw_project(project_root)
[2024-04-01T10:36:56.039+0000] {subprocess.py:93} INFO -   File "/home/***/.local/lib/python3.8/site-packages/dbt/config/project.py", line 208, in load_raw_project
[2024-04-01T10:36:56.040+0000] {subprocess.py:93} INFO -     project_dict = _load_yaml(project_yaml_filepath)
[2024-04-01T10:36:56.042+0000] {subprocess.py:93} INFO -   File "/home/***/.local/lib/python3.8/site-packages/dbt/config/project.py", line 97, in _load_yaml
[2024-04-01T10:36:56.042+0000] {subprocess.py:93} INFO -     contents = load_file_contents(path)
[2024-04-01T10:36:56.043+0000] {subprocess.py:93} INFO -   File "/home/***/.local/lib/python3.8/site-packages/dbt/clients/system.py", line 97, in load_file_contents
[2024-04-01T10:36:56.044+0000] {subprocess.py:93} INFO -     with open(path, "rb") as handle:
[2024-04-01T10:36:56.045+0000] {subprocess.py:93} INFO - OSError: [Errno 5] Input/output error: '/opt/***/proj/dbt_project.yml'
[2024-04-01T10:36:56.046+0000] {subprocess.py:93} INFO - 
[2024-04-01T10:36:58.332+0000] {subprocess.py:97} INFO - Command exited with return code 2
[2024-04-01T10:36:58.372+0000] {taskinstance.py:2698} ERROR - Task failed with exception
Traceback (most recent call last):
  File "/home/airflow/.local/lib/python3.8/site-packages/airflow/models/taskinstance.py", line 433, in _execute_task
    result = execute_callable(context=context, **execute_callable_kwargs)
  File "/home/airflow/.local/lib/python3.8/site-packages/airflow/operators/bash.py", line 212, in execute
    raise AirflowException(
airflow.exceptions.AirflowException: Bash command failed. The command returned a non-zero exit code 2.
[2024-04-01T10:36:58.426+0000] {taskinstance.py:1138} INFO - Marking task as UP_FOR_RETRY. dag_id=dag___fresness, task_id=run_model1, execution_date=20240315T000000, start_date=20240401T103612, end_date=20240401T103658
[2024-04-01T10:36:58.491+0000] {standard_task_runner.py:107} ERROR - Failed to execute job 244 for task run_model1 (Bash command failed. The command returned a non-zero exit code 2.; 486)
[2024-04-01T10:36:58.515+0000] {local_task_job_runner.py:234} INFO - Task exited with return code 1
[2024-04-01T10:36:58.606+0000] {taskinstance.py:3280} INFO - 0 downstream tasks scheduled from follow-on schedule check
