[2024-04-01T09:54:04.560+0000] {taskinstance.py:1956} INFO - Dependencies all met for dep_context=non-requeueable deps ti=<TaskInstance: dag___dbt.run_model1 scheduled__2024-03-30T06:00:00+00:00 [queued]>
[2024-04-01T09:54:04.642+0000] {taskinstance.py:1956} INFO - Dependencies all met for dep_context=requeueable deps ti=<TaskInstance: dag___dbt.run_model1 scheduled__2024-03-30T06:00:00+00:00 [queued]>
[2024-04-01T09:54:04.649+0000] {taskinstance.py:2170} INFO - Starting attempt 1 of 2
[2024-04-01T09:54:04.762+0000] {taskinstance.py:2191} INFO - Executing <Task(BashOperator): run_model1> on 2024-03-30 06:00:00+00:00
[2024-04-01T09:54:04.805+0000] {standard_task_runner.py:60} INFO - Started process 525 to run task
[2024-04-01T09:54:04.835+0000] {standard_task_runner.py:87} INFO - Running: ['***', 'tasks', 'run', 'dag___dbt', 'run_model1', 'scheduled__2024-03-30T06:00:00+00:00', '--job-id', '108', '--raw', '--subdir', 'DAGS_FOLDER/freshness_test_dag.py', '--cfg-path', '/tmp/tmplcpw5zb6']
[2024-04-01T09:54:04.844+0000] {standard_task_runner.py:88} INFO - Job 108: Subtask run_model1
[2024-04-01T09:54:05.196+0000] {task_command.py:423} INFO - Running <TaskInstance: dag___dbt.run_model1 scheduled__2024-03-30T06:00:00+00:00 [running]> on host 62dc842f1ceb
[2024-04-01T09:54:06.575+0000] {taskinstance.py:2480} INFO - Exporting env vars: AIRFLOW_CTX_DAG_OWNER='***' AIRFLOW_CTX_DAG_ID='dag___dbt' AIRFLOW_CTX_TASK_ID='run_model1' AIRFLOW_CTX_EXECUTION_DATE='2024-03-30T06:00:00+00:00' AIRFLOW_CTX_TRY_NUMBER='1' AIRFLOW_CTX_DAG_RUN_ID='scheduled__2024-03-30T06:00:00+00:00'
[2024-04-01T09:54:06.580+0000] {subprocess.py:63} INFO - Tmp dir root location: /tmp
[2024-04-01T09:54:06.604+0000] {subprocess.py:75} INFO - Running command: ['/usr/bin/bash', '-c', '/home/***/.local/bin/dbt run --models my_first_dbt_model my_second_dbt_model  --profiles-dir /home/***/.dbt --project-dir /opt/***/proj']
[2024-04-01T09:54:06.702+0000] {subprocess.py:86} INFO - Output:
[2024-04-01T09:54:42.506+0000] {job.py:213} ERROR - Job heartbeat got an exception
Traceback (most recent call last):
  File "/home/airflow/.local/lib/python3.8/site-packages/sqlalchemy/engine/base.py", line 3371, in _wrap_pool_connect
    return fn()
  File "/home/airflow/.local/lib/python3.8/site-packages/sqlalchemy/pool/base.py", line 327, in connect
    return _ConnectionFairy._checkout(self)
  File "/home/airflow/.local/lib/python3.8/site-packages/sqlalchemy/pool/base.py", line 894, in _checkout
    fairy = _ConnectionRecord.checkout(pool)
  File "/home/airflow/.local/lib/python3.8/site-packages/sqlalchemy/pool/base.py", line 493, in checkout
    rec = pool._do_get()
  File "/home/airflow/.local/lib/python3.8/site-packages/sqlalchemy/pool/impl.py", line 256, in _do_get
    return self._create_connection()
  File "/home/airflow/.local/lib/python3.8/site-packages/sqlalchemy/pool/base.py", line 273, in _create_connection
    return _ConnectionRecord(self)
  File "/home/airflow/.local/lib/python3.8/site-packages/sqlalchemy/pool/base.py", line 388, in __init__
    self.__connect()
  File "/home/airflow/.local/lib/python3.8/site-packages/sqlalchemy/pool/base.py", line 691, in __connect
    pool.logger.debug("Error on connect(): %s", e)
  File "/home/airflow/.local/lib/python3.8/site-packages/sqlalchemy/util/langhelpers.py", line 70, in __exit__
    compat.raise_(
  File "/home/airflow/.local/lib/python3.8/site-packages/sqlalchemy/util/compat.py", line 211, in raise_
    raise exception
  File "/home/airflow/.local/lib/python3.8/site-packages/sqlalchemy/pool/base.py", line 686, in __connect
    self.dbapi_connection = connection = pool._invoke_creator(self)
  File "/home/airflow/.local/lib/python3.8/site-packages/sqlalchemy/engine/create.py", line 574, in connect
    return dialect.connect(*cargs, **cparams)
  File "/home/airflow/.local/lib/python3.8/site-packages/sqlalchemy/engine/default.py", line 598, in connect
    return self.dbapi.connect(*cargs, **cparams)
  File "/home/airflow/.local/lib/python3.8/site-packages/psycopg2/__init__.py", line 122, in connect
    conn = _connect(dsn, connection_factory=connection_factory, **kwasync)
psycopg2.OperationalError: could not translate host name "postgres" to address: Temporary failure in name resolution


The above exception was the direct cause of the following exception:

Traceback (most recent call last):
  File "/home/airflow/.local/lib/python3.8/site-packages/airflow/jobs/job.py", line 187, in heartbeat
    self._merge_from(Job._fetch_from_db(self, session))
  File "/home/airflow/.local/lib/python3.8/site-packages/airflow/api_internal/internal_api_call.py", line 114, in wrapper
    return func(*args, **kwargs)
  File "/home/airflow/.local/lib/python3.8/site-packages/airflow/utils/session.py", line 76, in wrapper
    return func(*args, **kwargs)
  File "/home/airflow/.local/lib/python3.8/site-packages/airflow/jobs/job.py", line 308, in _fetch_from_db
    session.merge(job)
  File "/home/airflow/.local/lib/python3.8/site-packages/sqlalchemy/orm/session.py", line 3056, in merge
    return self._merge(
  File "/home/airflow/.local/lib/python3.8/site-packages/sqlalchemy/orm/session.py", line 3136, in _merge
    merged = self.get(
  File "/home/airflow/.local/lib/python3.8/site-packages/sqlalchemy/orm/session.py", line 2853, in get
    return self._get_impl(
  File "/home/airflow/.local/lib/python3.8/site-packages/sqlalchemy/orm/session.py", line 2975, in _get_impl
    return db_load_fn(
  File "/home/airflow/.local/lib/python3.8/site-packages/sqlalchemy/orm/loading.py", line 530, in load_on_pk_identity
    session.execute(
  File "/home/airflow/.local/lib/python3.8/site-packages/sqlalchemy/orm/session.py", line 1716, in execute
    conn = self._connection_for_bind(bind)
  File "/home/airflow/.local/lib/python3.8/site-packages/sqlalchemy/orm/session.py", line 1555, in _connection_for_bind
    return self._transaction._connection_for_bind(
  File "/home/airflow/.local/lib/python3.8/site-packages/sqlalchemy/orm/session.py", line 750, in _connection_for_bind
    conn = bind.connect()
  File "/home/airflow/.local/lib/python3.8/site-packages/sqlalchemy/future/engine.py", line 412, in connect
    return super(Engine, self).connect()
  File "/home/airflow/.local/lib/python3.8/site-packages/sqlalchemy/engine/base.py", line 3325, in connect
    return self._connection_cls(self, close_with_result=close_with_result)
  File "/home/airflow/.local/lib/python3.8/site-packages/sqlalchemy/engine/base.py", line 96, in __init__
    else engine.raw_connection()
  File "/home/airflow/.local/lib/python3.8/site-packages/sqlalchemy/engine/base.py", line 3404, in raw_connection
    return self._wrap_pool_connect(self.pool.connect, _connection)
  File "/home/airflow/.local/lib/python3.8/site-packages/sqlalchemy/engine/base.py", line 3374, in _wrap_pool_connect
    Connection._handle_dbapi_exception_noconnection(
  File "/home/airflow/.local/lib/python3.8/site-packages/sqlalchemy/engine/base.py", line 2208, in _handle_dbapi_exception_noconnection
    util.raise_(
  File "/home/airflow/.local/lib/python3.8/site-packages/sqlalchemy/util/compat.py", line 211, in raise_
    raise exception
  File "/home/airflow/.local/lib/python3.8/site-packages/sqlalchemy/engine/base.py", line 3371, in _wrap_pool_connect
    return fn()
  File "/home/airflow/.local/lib/python3.8/site-packages/sqlalchemy/pool/base.py", line 327, in connect
    return _ConnectionFairy._checkout(self)
  File "/home/airflow/.local/lib/python3.8/site-packages/sqlalchemy/pool/base.py", line 894, in _checkout
    fairy = _ConnectionRecord.checkout(pool)
  File "/home/airflow/.local/lib/python3.8/site-packages/sqlalchemy/pool/base.py", line 493, in checkout
    rec = pool._do_get()
  File "/home/airflow/.local/lib/python3.8/site-packages/sqlalchemy/pool/impl.py", line 256, in _do_get
    return self._create_connection()
  File "/home/airflow/.local/lib/python3.8/site-packages/sqlalchemy/pool/base.py", line 273, in _create_connection
    return _ConnectionRecord(self)
  File "/home/airflow/.local/lib/python3.8/site-packages/sqlalchemy/pool/base.py", line 388, in __init__
    self.__connect()
  File "/home/airflow/.local/lib/python3.8/site-packages/sqlalchemy/pool/base.py", line 691, in __connect
    pool.logger.debug("Error on connect(): %s", e)
  File "/home/airflow/.local/lib/python3.8/site-packages/sqlalchemy/util/langhelpers.py", line 70, in __exit__
    compat.raise_(
  File "/home/airflow/.local/lib/python3.8/site-packages/sqlalchemy/util/compat.py", line 211, in raise_
    raise exception
  File "/home/airflow/.local/lib/python3.8/site-packages/sqlalchemy/pool/base.py", line 686, in __connect
    self.dbapi_connection = connection = pool._invoke_creator(self)
  File "/home/airflow/.local/lib/python3.8/site-packages/sqlalchemy/engine/create.py", line 574, in connect
    return dialect.connect(*cargs, **cparams)
  File "/home/airflow/.local/lib/python3.8/site-packages/sqlalchemy/engine/default.py", line 598, in connect
    return self.dbapi.connect(*cargs, **cparams)
  File "/home/airflow/.local/lib/python3.8/site-packages/psycopg2/__init__.py", line 122, in connect
    conn = _connect(dsn, connection_factory=connection_factory, **kwasync)
sqlalchemy.exc.OperationalError: (psycopg2.OperationalError) could not translate host name "postgres" to address: Temporary failure in name resolution

(Background on this error at: https://sqlalche.me/e/14/e3q8)
[2024-04-01T09:54:43.014+0000] {job.py:221} ERROR - Job heartbeat failed with error. Scheduler is in unhealthy state
[2024-04-01T09:54:56.524+0000] {subprocess.py:93} INFO - [0m09:54:56  Encountered an error:
[2024-04-01T09:54:56.531+0000] {subprocess.py:93} INFO - [Errno 5] Input/output error: '/opt/***/proj/dbt_project.yml'
[2024-04-01T09:54:56.554+0000] {subprocess.py:93} INFO - [0m09:54:56  Traceback (most recent call last):
[2024-04-01T09:54:56.555+0000] {subprocess.py:93} INFO -   File "/home/***/.local/lib/python3.8/site-packages/dbt/cli/requires.py", line 91, in wrapper
[2024-04-01T09:54:56.558+0000] {subprocess.py:93} INFO -     result, success = func(*args, **kwargs)
[2024-04-01T09:54:56.560+0000] {subprocess.py:93} INFO -   File "/home/***/.local/lib/python3.8/site-packages/dbt/cli/requires.py", line 45, in wrapper
[2024-04-01T09:54:56.562+0000] {subprocess.py:93} INFO -     flags = Flags(ctx)
[2024-04-01T09:54:56.563+0000] {subprocess.py:93} INFO -   File "/home/***/.local/lib/python3.8/site-packages/dbt/cli/flags.py", line 239, in __init__
[2024-04-01T09:54:56.564+0000] {subprocess.py:93} INFO -     object.__setattr__(self, "LOG_PATH", default_log_path(project_dir, version_check))
[2024-04-01T09:54:56.566+0000] {subprocess.py:93} INFO -   File "/home/***/.local/lib/python3.8/site-packages/dbt/cli/resolvers.py", line 25, in default_log_path
[2024-04-01T09:54:56.572+0000] {subprocess.py:93} INFO -     partial = PartialProject.from_project_root(str(project_dir), verify_version=verify_version)
[2024-04-01T09:54:56.573+0000] {subprocess.py:93} INFO -   File "/home/***/.local/lib/python3.8/site-packages/dbt/config/project.py", line 565, in from_project_root
[2024-04-01T09:54:56.575+0000] {subprocess.py:93} INFO -     project_dict = load_raw_project(project_root)
[2024-04-01T09:54:56.577+0000] {subprocess.py:93} INFO -   File "/home/***/.local/lib/python3.8/site-packages/dbt/config/project.py", line 208, in load_raw_project
[2024-04-01T09:54:56.579+0000] {subprocess.py:93} INFO -     project_dict = _load_yaml(project_yaml_filepath)
[2024-04-01T09:54:56.580+0000] {subprocess.py:93} INFO -   File "/home/***/.local/lib/python3.8/site-packages/dbt/config/project.py", line 97, in _load_yaml
[2024-04-01T09:54:56.581+0000] {subprocess.py:93} INFO -     contents = load_file_contents(path)
[2024-04-01T09:54:56.585+0000] {subprocess.py:93} INFO -   File "/home/***/.local/lib/python3.8/site-packages/dbt/clients/system.py", line 97, in load_file_contents
[2024-04-01T09:54:56.587+0000] {subprocess.py:93} INFO -     with open(path, "rb") as handle:
[2024-04-01T09:54:56.596+0000] {subprocess.py:93} INFO - OSError: [Errno 5] Input/output error: '/opt/***/proj/dbt_project.yml'
[2024-04-01T09:54:56.597+0000] {subprocess.py:93} INFO - 
[2024-04-01T09:54:57.284+0000] {subprocess.py:97} INFO - Command exited with return code 2
[2024-04-01T09:54:57.462+0000] {taskinstance.py:2698} ERROR - Task failed with exception
Traceback (most recent call last):
  File "/home/airflow/.local/lib/python3.8/site-packages/airflow/models/taskinstance.py", line 433, in _execute_task
    result = execute_callable(context=context, **execute_callable_kwargs)
  File "/home/airflow/.local/lib/python3.8/site-packages/airflow/operators/bash.py", line 212, in execute
    raise AirflowException(
airflow.exceptions.AirflowException: Bash command failed. The command returned a non-zero exit code 2.
[2024-04-01T09:54:57.606+0000] {taskinstance.py:1138} INFO - Marking task as UP_FOR_RETRY. dag_id=dag___dbt, task_id=run_model1, execution_date=20240330T060000, start_date=20240401T095404, end_date=20240401T095457
[2024-04-01T09:54:57.811+0000] {standard_task_runner.py:107} ERROR - Failed to execute job 108 for task run_model1 (Bash command failed. The command returned a non-zero exit code 2.; 525)
[2024-04-01T09:54:57.892+0000] {local_task_job_runner.py:234} INFO - Task exited with return code 1
[2024-04-01T09:54:58.250+0000] {taskinstance.py:3280} INFO - 0 downstream tasks scheduled from follow-on schedule check
