[2024-04-01T10:36:12.137+0000] {taskinstance.py:1956} INFO - Dependencies all met for dep_context=non-requeueable deps ti=<TaskInstance: dag___fresness.run_model1 manual__2024-04-01T10:36:05.229822+00:00 [queued]>
[2024-04-01T10:36:12.210+0000] {taskinstance.py:1956} INFO - Dependencies all met for dep_context=requeueable deps ti=<TaskInstance: dag___fresness.run_model1 manual__2024-04-01T10:36:05.229822+00:00 [queued]>
[2024-04-01T10:36:12.213+0000] {taskinstance.py:2170} INFO - Starting attempt 1 of 2
[2024-04-01T10:36:12.381+0000] {taskinstance.py:2191} INFO - Executing <Task(BashOperator): run_model1> on 2024-04-01 10:36:05.229822+00:00
[2024-04-01T10:36:12.419+0000] {standard_task_runner.py:60} INFO - Started process 485 to run task
[2024-04-01T10:36:12.418+0000] {standard_task_runner.py:87} INFO - Running: ['***', 'tasks', 'run', 'dag___fresness', 'run_model1', 'manual__2024-04-01T10:36:05.229822+00:00', '--job-id', '243', '--raw', '--subdir', 'DAGS_FOLDER/dbt_dag.py', '--cfg-path', '/tmp/tmp57w9rdgv']
[2024-04-01T10:36:12.439+0000] {standard_task_runner.py:88} INFO - Job 243: Subtask run_model1
[2024-04-01T10:36:12.869+0000] {task_command.py:423} INFO - Running <TaskInstance: dag___fresness.run_model1 manual__2024-04-01T10:36:05.229822+00:00 [running]> on host 62dc842f1ceb
[2024-04-01T10:36:13.400+0000] {taskinstance.py:2480} INFO - Exporting env vars: AIRFLOW_CTX_DAG_OWNER='***' AIRFLOW_CTX_DAG_ID='dag___fresness' AIRFLOW_CTX_TASK_ID='run_model1' AIRFLOW_CTX_EXECUTION_DATE='2024-04-01T10:36:05.229822+00:00' AIRFLOW_CTX_TRY_NUMBER='1' AIRFLOW_CTX_DAG_RUN_ID='manual__2024-04-01T10:36:05.229822+00:00'
[2024-04-01T10:36:13.414+0000] {subprocess.py:63} INFO - Tmp dir root location: /tmp
[2024-04-01T10:36:13.418+0000] {subprocess.py:75} INFO - Running command: ['/usr/bin/bash', '-c', '/home/***/.local/bin/dbt run --models  --profiles-dir /home/***/.dbt --project-dir /opt/***/proj']
[2024-04-01T10:36:13.513+0000] {subprocess.py:86} INFO - Output:
[2024-04-01T10:36:53.040+0000] {subprocess.py:93} INFO - [0m10:36:53  Running with dbt=1.7.10
[2024-04-01T10:36:56.960+0000] {subprocess.py:93} INFO - [0m10:36:56  Registered adapter: postgres=1.7.10
[2024-04-01T10:36:57.734+0000] {subprocess.py:93} INFO - [0m10:36:57  Encountered an error:
[2024-04-01T10:36:57.735+0000] {subprocess.py:93} INFO - [Errno 5] Input/output error: '/opt/***/proj/dbt_packages/dbt_date/dbt_project.yml'
[2024-04-01T10:36:57.743+0000] {subprocess.py:93} INFO - [0m10:36:57  Traceback (most recent call last):
[2024-04-01T10:36:57.745+0000] {subprocess.py:93} INFO -   File "/home/***/.local/lib/python3.8/site-packages/dbt/cli/requires.py", line 91, in wrapper
[2024-04-01T10:36:57.745+0000] {subprocess.py:93} INFO -     result, success = func(*args, **kwargs)
[2024-04-01T10:36:57.746+0000] {subprocess.py:93} INFO -   File "/home/***/.local/lib/python3.8/site-packages/dbt/cli/requires.py", line 76, in wrapper
[2024-04-01T10:36:57.747+0000] {subprocess.py:93} INFO -     return func(*args, **kwargs)
[2024-04-01T10:36:57.748+0000] {subprocess.py:93} INFO -   File "/home/***/.local/lib/python3.8/site-packages/dbt/cli/requires.py", line 169, in wrapper
[2024-04-01T10:36:57.749+0000] {subprocess.py:93} INFO -     return func(*args, **kwargs)
[2024-04-01T10:36:57.749+0000] {subprocess.py:93} INFO -   File "/home/***/.local/lib/python3.8/site-packages/dbt/cli/requires.py", line 198, in wrapper
[2024-04-01T10:36:57.750+0000] {subprocess.py:93} INFO -     return func(*args, **kwargs)
[2024-04-01T10:36:57.751+0000] {subprocess.py:93} INFO -   File "/home/***/.local/lib/python3.8/site-packages/dbt/cli/requires.py", line 245, in wrapper
[2024-04-01T10:36:57.752+0000] {subprocess.py:93} INFO -     return func(*args, **kwargs)
[2024-04-01T10:36:57.752+0000] {subprocess.py:93} INFO -   File "/home/***/.local/lib/python3.8/site-packages/dbt/cli/requires.py", line 271, in wrapper
[2024-04-01T10:36:57.753+0000] {subprocess.py:93} INFO -     ctx.obj["manifest"] = parse_manifest(
[2024-04-01T10:36:57.754+0000] {subprocess.py:93} INFO -   File "/home/***/.local/lib/python3.8/site-packages/dbt/parser/manifest.py", line 1798, in parse_manifest
[2024-04-01T10:36:57.758+0000] {subprocess.py:93} INFO -     manifest = ManifestLoader.get_full_manifest(
[2024-04-01T10:36:57.759+0000] {subprocess.py:93} INFO -   File "/home/***/.local/lib/python3.8/site-packages/dbt/parser/manifest.py", line 311, in get_full_manifest
[2024-04-01T10:36:57.760+0000] {subprocess.py:93} INFO -     loader = cls(
[2024-04-01T10:36:57.761+0000] {subprocess.py:93} INFO -   File "/home/***/.local/lib/python3.8/site-packages/dbt/parser/manifest.py", line 262, in __init__
[2024-04-01T10:36:57.762+0000] {subprocess.py:93} INFO -     self.manifest.state_check = self.build_manifest_state_check()
[2024-04-01T10:36:57.763+0000] {subprocess.py:93} INFO -   File "/home/***/.local/lib/python3.8/site-packages/dbt/parser/manifest.py", line 985, in build_manifest_state_check
[2024-04-01T10:36:57.764+0000] {subprocess.py:93} INFO -     with open(path) as fp:
[2024-04-01T10:36:57.765+0000] {subprocess.py:93} INFO - OSError: [Errno 5] Input/output error: '/opt/***/proj/dbt_packages/dbt_date/dbt_project.yml'
[2024-04-01T10:36:57.766+0000] {subprocess.py:93} INFO - 
[2024-04-01T10:37:00.228+0000] {subprocess.py:97} INFO - Command exited with return code 2
[2024-04-01T10:37:00.278+0000] {taskinstance.py:2698} ERROR - Task failed with exception
Traceback (most recent call last):
  File "/home/airflow/.local/lib/python3.8/site-packages/airflow/models/taskinstance.py", line 433, in _execute_task
    result = execute_callable(context=context, **execute_callable_kwargs)
  File "/home/airflow/.local/lib/python3.8/site-packages/airflow/operators/bash.py", line 212, in execute
    raise AirflowException(
airflow.exceptions.AirflowException: Bash command failed. The command returned a non-zero exit code 2.
[2024-04-01T10:37:00.292+0000] {taskinstance.py:1138} INFO - Marking task as UP_FOR_RETRY. dag_id=dag___fresness, task_id=run_model1, execution_date=20240401T103605, start_date=20240401T103612, end_date=20240401T103700
[2024-04-01T10:37:00.359+0000] {standard_task_runner.py:107} ERROR - Failed to execute job 243 for task run_model1 (Bash command failed. The command returned a non-zero exit code 2.; 485)
[2024-04-01T10:37:00.414+0000] {local_task_job_runner.py:234} INFO - Task exited with return code 1
[2024-04-01T10:37:00.594+0000] {taskinstance.py:3280} INFO - 0 downstream tasks scheduled from follow-on schedule check
