[2024-04-01T09:55:20.878+0000] {taskinstance.py:1956} INFO - Dependencies all met for dep_context=non-requeueable deps ti=<TaskInstance: dag___dbt.dbt_data_quality_checks scheduled__2024-03-31T01:00:00+00:00 [queued]>
[2024-04-01T09:55:20.906+0000] {taskinstance.py:1956} INFO - Dependencies all met for dep_context=requeueable deps ti=<TaskInstance: dag___dbt.dbt_data_quality_checks scheduled__2024-03-31T01:00:00+00:00 [queued]>
[2024-04-01T09:55:20.907+0000] {taskinstance.py:2170} INFO - Starting attempt 1 of 2
[2024-04-01T09:55:20.955+0000] {taskinstance.py:2191} INFO - Executing <Task(BashOperator): dbt_data_quality_checks> on 2024-03-31 01:00:00+00:00
[2024-04-01T09:55:20.968+0000] {standard_task_runner.py:60} INFO - Started process 559 to run task
[2024-04-01T09:55:20.974+0000] {standard_task_runner.py:87} INFO - Running: ['***', 'tasks', 'run', 'dag___dbt', 'dbt_data_quality_checks', 'scheduled__2024-03-31T01:00:00+00:00', '--job-id', '112', '--raw', '--subdir', 'DAGS_FOLDER/dbt_dag.py', '--cfg-path', '/tmp/tmpjjqp116a']
[2024-04-01T09:55:20.979+0000] {standard_task_runner.py:88} INFO - Job 112: Subtask dbt_data_quality_checks
[2024-04-01T09:55:21.114+0000] {task_command.py:423} INFO - Running <TaskInstance: dag___dbt.dbt_data_quality_checks scheduled__2024-03-31T01:00:00+00:00 [running]> on host 62dc842f1ceb
[2024-04-01T09:55:21.332+0000] {taskinstance.py:2480} INFO - Exporting env vars: AIRFLOW_CTX_DAG_OWNER='***' AIRFLOW_CTX_DAG_ID='dag___dbt' AIRFLOW_CTX_TASK_ID='dbt_data_quality_checks' AIRFLOW_CTX_EXECUTION_DATE='2024-03-31T01:00:00+00:00' AIRFLOW_CTX_TRY_NUMBER='1' AIRFLOW_CTX_DAG_RUN_ID='scheduled__2024-03-31T01:00:00+00:00'
[2024-04-01T09:55:21.337+0000] {subprocess.py:63} INFO - Tmp dir root location: /tmp
[2024-04-01T09:55:21.352+0000] {subprocess.py:75} INFO - Running command: ['/usr/bin/bash', '-c', '/home/***/.local/bin/dbt test --profiles-dir /home/***/.dbt --project-dir /opt/***/proj']
[2024-04-01T09:55:21.385+0000] {subprocess.py:86} INFO - Output:
[2024-04-01T09:55:33.465+0000] {subprocess.py:93} INFO - [0m09:55:33  Running with dbt=1.7.10
[2024-04-01T09:55:36.031+0000] {subprocess.py:93} INFO - [0m09:55:36  Registered adapter: postgres=1.7.10
[2024-04-01T09:55:56.874+0000] {subprocess.py:93} INFO - [0m09:55:56  Found 34 models, 2 operations, 5 tests, 1 source, 0 exposures, 0 metrics, 1407 macros, 0 groups, 0 semantic models
[2024-04-01T09:55:56.889+0000] {subprocess.py:93} INFO - [0m09:55:56
[2024-04-01T09:55:58.029+0000] {subprocess.py:93} INFO - [0m09:55:58
[2024-04-01T09:55:58.035+0000] {subprocess.py:93} INFO - [0m09:55:58  Running 1 on-run-start hook
[2024-04-01T09:55:58.450+0000] {subprocess.py:93} INFO - [0m09:55:58  1 of 1 START hook: elementary.on-run-start.0 ................................... [RUN]
[2024-04-01T09:55:58.456+0000] {subprocess.py:93} INFO - [0m09:55:58  1 of 1 OK hook: elementary.on-run-start.0 ...................................... [[32mOK[0m in 0.00s]
[2024-04-01T09:55:58.467+0000] {subprocess.py:93} INFO - [0m09:55:58
[2024-04-01T09:55:58.475+0000] {subprocess.py:93} INFO - [0m09:55:58  Concurrency: 1 threads (target='dev')
[2024-04-01T09:55:58.481+0000] {subprocess.py:93} INFO - [0m09:55:58
[2024-04-01T09:55:58.517+0000] {subprocess.py:93} INFO - [0m09:55:58  1 of 5 START test elementary_freshness_anomalies_raw_orders_creation_date ...... [RUN]
[2024-04-01T09:56:01.579+0000] {subprocess.py:93} INFO - [0m09:56:01  Elementary: Started running data monitors on: POSTGRES.PUBLIC.RAW_ORDERS
[2024-04-01T09:56:04.245+0000] {subprocess.py:93} INFO - [0m09:56:04  Elementary: Finished running data monitors on: POSTGRES.PUBLIC.RAW_ORDERS
[2024-04-01T09:56:06.604+0000] {subprocess.py:93} INFO - [0m09:56:06  1 of 5 PASS elementary_freshness_anomalies_raw_orders_creation_date ............ [[32mPASS[0m in 8.08s]
[2024-04-01T09:56:06.622+0000] {subprocess.py:93} INFO - [0m09:56:06  2 of 5 START test not_null_my_second_dbt_model_id .............................. [RUN]
[2024-04-01T09:56:06.999+0000] {subprocess.py:93} INFO - [0m09:56:06  2 of 5 ERROR not_null_my_second_dbt_model_id ................................... [[31mERROR[0m in 0.37s]
[2024-04-01T09:56:07.023+0000] {subprocess.py:93} INFO - [0m09:56:07  3 of 5 START test not_null_raw_orders_creation_date ............................ [RUN]
[2024-04-01T09:56:07.472+0000] {subprocess.py:93} INFO - [0m09:56:07  3 of 5 PASS not_null_raw_orders_creation_date .................................. [[32mPASS[0m in 0.44s]
[2024-04-01T09:56:07.493+0000] {subprocess.py:93} INFO - [0m09:56:07  4 of 5 START test unique_my_first_dbt_model_id ................................. [RUN]
[2024-04-01T09:56:08.093+0000] {subprocess.py:93} INFO - [0m09:56:08  4 of 5 PASS unique_my_first_dbt_model_id ....................................... [[32mPASS[0m in 0.59s]
[2024-04-01T09:56:08.109+0000] {subprocess.py:93} INFO - [0m09:56:08  5 of 5 START test unique_my_second_dbt_model_id ................................ [RUN]
[2024-04-01T09:56:08.603+0000] {subprocess.py:93} INFO - [0m09:56:08  5 of 5 ERROR unique_my_second_dbt_model_id ..................................... [[31mERROR[0m in 0.49s]
[2024-04-01T09:56:08.773+0000] {subprocess.py:93} INFO - [0m09:56:08
[2024-04-01T09:56:08.777+0000] {subprocess.py:93} INFO - [0m09:56:08  Running 1 on-run-end hook
[2024-04-01T09:56:17.241+0000] {subprocess.py:93} INFO - [0m09:56:17  1 of 1 START hook: elementary.on-run-end.0 ..................................... [RUN]
[2024-04-01T09:56:17.244+0000] {subprocess.py:93} INFO - [0m09:56:17  1 of 1 OK hook: elementary.on-run-end.0 ........................................ [[32mOK[0m in 0.00s]
[2024-04-01T09:56:17.247+0000] {subprocess.py:93} INFO - [0m09:56:17
[2024-04-01T09:56:17.260+0000] {subprocess.py:93} INFO - [0m09:56:17
[2024-04-01T09:56:17.265+0000] {subprocess.py:93} INFO - [0m09:56:17  Finished running 5 tests, 2 hooks in 0 hours 0 minutes and 20.37 seconds (20.37s).
[2024-04-01T09:56:17.396+0000] {subprocess.py:93} INFO - [0m09:56:17
[2024-04-01T09:56:17.401+0000] {subprocess.py:93} INFO - [0m09:56:17  [31mCompleted with 2 errors and 0 warnings:[0m
[2024-04-01T09:56:17.406+0000] {subprocess.py:93} INFO - [0m09:56:17
[2024-04-01T09:56:17.407+0000] {subprocess.py:93} INFO - [0m09:56:17    Database Error in test not_null_my_second_dbt_model_id (models/example/schema.yml)
[2024-04-01T09:56:17.408+0000] {subprocess.py:93} INFO -   ERREUR:  la relation Â« public.my_second_dbt_model Â» n'existe pas
[2024-04-01T09:56:17.409+0000] {subprocess.py:93} INFO -   LINE 14: from "postgres"."public"."my_second_dbt_model"
[2024-04-01T09:56:17.410+0000] {subprocess.py:93} INFO -                 ^
[2024-04-01T09:56:17.411+0000] {subprocess.py:93} INFO -   compiled Code at target/run/proj/models/example/schema.yml/not_null_my_second_dbt_model_id.sql
[2024-04-01T09:56:17.412+0000] {subprocess.py:93} INFO - [0m09:56:17
[2024-04-01T09:56:17.412+0000] {subprocess.py:93} INFO - [0m09:56:17    Database Error in test unique_my_second_dbt_model_id (models/example/schema.yml)
[2024-04-01T09:56:17.413+0000] {subprocess.py:93} INFO -   ERREUR:  la relation Â« public.my_second_dbt_model Â» n'existe pas
[2024-04-01T09:56:17.414+0000] {subprocess.py:93} INFO -   LINE 15: from "postgres"."public"."my_second_dbt_model"
[2024-04-01T09:56:17.415+0000] {subprocess.py:93} INFO -                 ^
[2024-04-01T09:56:17.416+0000] {subprocess.py:93} INFO -   compiled Code at target/run/proj/models/example/schema.yml/unique_my_second_dbt_model_id.sql
[2024-04-01T09:56:17.417+0000] {subprocess.py:93} INFO - [0m09:56:17
[2024-04-01T09:56:17.417+0000] {subprocess.py:93} INFO - [0m09:56:17  Done. PASS=3 WARN=0 ERROR=2 SKIP=0 TOTAL=5
[2024-04-01T09:56:18.733+0000] {subprocess.py:97} INFO - Command exited with return code 1
[2024-04-01T09:56:18.771+0000] {taskinstance.py:2698} ERROR - Task failed with exception
Traceback (most recent call last):
  File "/home/airflow/.local/lib/python3.8/site-packages/airflow/models/taskinstance.py", line 433, in _execute_task
    result = execute_callable(context=context, **execute_callable_kwargs)
  File "/home/airflow/.local/lib/python3.8/site-packages/airflow/operators/bash.py", line 212, in execute
    raise AirflowException(
airflow.exceptions.AirflowException: Bash command failed. The command returned a non-zero exit code 1.
[2024-04-01T09:56:18.787+0000] {taskinstance.py:1138} INFO - Marking task as UP_FOR_RETRY. dag_id=dag___dbt, task_id=dbt_data_quality_checks, execution_date=20240331T010000, start_date=20240401T095520, end_date=20240401T095618
[2024-04-01T09:56:18.852+0000] {standard_task_runner.py:107} ERROR - Failed to execute job 112 for task dbt_data_quality_checks (Bash command failed. The command returned a non-zero exit code 1.; 559)
[2024-04-01T09:56:18.879+0000] {local_task_job_runner.py:234} INFO - Task exited with return code 1
[2024-04-01T09:56:18.962+0000] {taskinstance.py:3280} INFO - 0 downstream tasks scheduled from follow-on schedule check
