[2024-03-29T00:01:05.085+0000] {taskinstance.py:1956} INFO - Dependencies all met for dep_context=non-requeueable deps ti=<TaskInstance: dag___dbt.dbt_data_quality_checks scheduled__2024-03-28T00:00:00+00:00 [queued]>
[2024-03-29T00:01:05.097+0000] {taskinstance.py:1956} INFO - Dependencies all met for dep_context=requeueable deps ti=<TaskInstance: dag___dbt.dbt_data_quality_checks scheduled__2024-03-28T00:00:00+00:00 [queued]>
[2024-03-29T00:01:05.098+0000] {taskinstance.py:2170} INFO - Starting attempt 1 of 2
[2024-03-29T00:01:05.120+0000] {taskinstance.py:2191} INFO - Executing <Task(BashOperator): dbt_data_quality_checks> on 2024-03-28 00:00:00+00:00
[2024-03-29T00:01:05.128+0000] {standard_task_runner.py:60} INFO - Started process 16875 to run task
[2024-03-29T00:01:05.133+0000] {standard_task_runner.py:87} INFO - Running: ['***', 'tasks', 'run', 'dag___dbt', 'dbt_data_quality_checks', 'scheduled__2024-03-28T00:00:00+00:00', '--job-id', '68', '--raw', '--subdir', 'DAGS_FOLDER/dbt_dag.py', '--cfg-path', '/tmp/tmpsiajb2to']
[2024-03-29T00:01:05.138+0000] {standard_task_runner.py:88} INFO - Job 68: Subtask dbt_data_quality_checks
[2024-03-29T00:01:05.212+0000] {task_command.py:423} INFO - Running <TaskInstance: dag___dbt.dbt_data_quality_checks scheduled__2024-03-28T00:00:00+00:00 [running]> on host 62dc842f1ceb
[2024-03-29T00:01:05.356+0000] {taskinstance.py:2480} INFO - Exporting env vars: AIRFLOW_CTX_DAG_OWNER='***' AIRFLOW_CTX_DAG_ID='dag___dbt' AIRFLOW_CTX_TASK_ID='dbt_data_quality_checks' AIRFLOW_CTX_EXECUTION_DATE='2024-03-28T00:00:00+00:00' AIRFLOW_CTX_TRY_NUMBER='1' AIRFLOW_CTX_DAG_RUN_ID='scheduled__2024-03-28T00:00:00+00:00'
[2024-03-29T00:01:05.360+0000] {subprocess.py:63} INFO - Tmp dir root location: /tmp
[2024-03-29T00:01:05.361+0000] {subprocess.py:75} INFO - Running command: ['/usr/bin/bash', '-c', '/home/***/.local/bin/dbt test --profiles-dir /home/***/.dbt --project-dir /opt/***/proj']
[2024-03-29T00:01:05.378+0000] {subprocess.py:86} INFO - Output:
[2024-03-29T00:01:09.969+0000] {subprocess.py:93} INFO - [0m00:01:09  Running with dbt=1.7.10
[2024-03-29T00:01:10.910+0000] {subprocess.py:93} INFO - [0m00:01:10  Registered adapter: postgres=1.7.10
[2024-03-29T00:01:30.837+0000] {subprocess.py:93} INFO - [0m00:01:30  Found 34 models, 2 operations, 5 tests, 1 source, 0 exposures, 0 metrics, 1407 macros, 0 groups, 0 semantic models
[2024-03-29T00:01:30.844+0000] {subprocess.py:93} INFO - [0m00:01:30
[2024-03-29T00:01:31.426+0000] {subprocess.py:93} INFO - [0m00:01:31
[2024-03-29T00:01:31.427+0000] {subprocess.py:93} INFO - [0m00:01:31  Running 1 on-run-start hook
[2024-03-29T00:01:31.627+0000] {subprocess.py:93} INFO - [0m00:01:31  1 of 1 START hook: elementary.on-run-start.0 ................................... [RUN]
[2024-03-29T00:01:31.629+0000] {subprocess.py:93} INFO - [0m00:01:31  1 of 1 OK hook: elementary.on-run-start.0 ...................................... [[32mOK[0m in 0.00s]
[2024-03-29T00:01:31.630+0000] {subprocess.py:93} INFO - [0m00:01:31
[2024-03-29T00:01:31.634+0000] {subprocess.py:93} INFO - [0m00:01:31  Concurrency: 1 threads (target='dev')
[2024-03-29T00:01:31.637+0000] {subprocess.py:93} INFO - [0m00:01:31
[2024-03-29T00:01:31.654+0000] {subprocess.py:93} INFO - [0m00:01:31  1 of 5 START test elementary_freshness_anomalies_raw_orders_minute__1__creation_date  [RUN]
[2024-03-29T00:01:32.010+0000] {subprocess.py:93} INFO - [0m00:01:32  1 of 5 ERROR elementary_freshness_anomalies_raw_orders_minute__1__creation_date  [[31mERROR[0m in 0.35s]
[2024-03-29T00:01:32.017+0000] {subprocess.py:93} INFO - [0m00:01:32  2 of 5 START test not_null_my_second_dbt_model_id .............................. [RUN]
[2024-03-29T00:01:32.747+0000] {subprocess.py:93} INFO - [0m00:01:32  2 of 5 PASS not_null_my_second_dbt_model_id .................................... [[32mPASS[0m in 0.73s]
[2024-03-29T00:01:32.753+0000] {subprocess.py:93} INFO - [0m00:01:32  3 of 5 START test not_null_raw_orders_creation_date ............................ [RUN]
[2024-03-29T00:01:32.957+0000] {subprocess.py:93} INFO - [0m00:01:32  3 of 5 PASS not_null_raw_orders_creation_date .................................. [[32mPASS[0m in 0.20s]
[2024-03-29T00:01:32.963+0000] {subprocess.py:93} INFO - [0m00:01:32  4 of 5 START test unique_my_first_dbt_model_id ................................. [RUN]
[2024-03-29T00:01:33.251+0000] {subprocess.py:93} INFO - [0m00:01:33  4 of 5 PASS unique_my_first_dbt_model_id ....................................... [[32mPASS[0m in 0.29s]
[2024-03-29T00:01:33.259+0000] {subprocess.py:93} INFO - [0m00:01:33  5 of 5 START test unique_my_second_dbt_model_id ................................ [RUN]
[2024-03-29T00:01:33.472+0000] {subprocess.py:93} INFO - [0m00:01:33  5 of 5 PASS unique_my_second_dbt_model_id ...................................... [[32mPASS[0m in 0.21s]
[2024-03-29T00:01:33.571+0000] {subprocess.py:93} INFO - [0m00:01:33
[2024-03-29T00:01:33.573+0000] {subprocess.py:93} INFO - [0m00:01:33  Running 1 on-run-end hook
[2024-03-29T00:01:36.785+0000] {subprocess.py:93} INFO - [0m00:01:36  1 of 1 START hook: elementary.on-run-end.0 ..................................... [RUN]
[2024-03-29T00:01:36.787+0000] {subprocess.py:93} INFO - [0m00:01:36  1 of 1 OK hook: elementary.on-run-end.0 ........................................ [[32mOK[0m in 0.00s]
[2024-03-29T00:01:36.789+0000] {subprocess.py:93} INFO - [0m00:01:36
[2024-03-29T00:01:36.798+0000] {subprocess.py:93} INFO - [0m00:01:36
[2024-03-29T00:01:36.801+0000] {subprocess.py:93} INFO - [0m00:01:36  Finished running 5 tests, 2 hooks in 0 hours 0 minutes and 5.95 seconds (5.95s).
[2024-03-29T00:01:36.904+0000] {subprocess.py:93} INFO - [0m00:01:36
[2024-03-29T00:01:36.906+0000] {subprocess.py:93} INFO - [0m00:01:36  [31mCompleted with 1 error and 0 warnings:[0m
[2024-03-29T00:01:36.907+0000] {subprocess.py:93} INFO - [0m00:01:36
[2024-03-29T00:01:36.909+0000] {subprocess.py:93} INFO - [0m00:01:36    Compilation Error in test elementary_freshness_anomalies_raw_orders_minute__1__creation_date (models/example/schema.yml)
[2024-03-29T00:01:36.910+0000] {subprocess.py:93} INFO -   time_bucket.period value should be one of ['hour', 'day', 'week', 'month'], got: minute
[2024-03-29T00:01:36.911+0000] {subprocess.py:93} INFO - 
[2024-03-29T00:01:36.911+0000] {subprocess.py:93} INFO -   > in macro validate_time_bucket (macros/edr/tests/test_configuration/get_time_bucket.sql)
[2024-03-29T00:01:36.912+0000] {subprocess.py:93} INFO -   > called by macro get_time_bucket (macros/edr/tests/test_configuration/get_time_bucket.sql)
[2024-03-29T00:01:36.912+0000] {subprocess.py:93} INFO -   > called by macro get_anomalies_test_configuration (macros/edr/tests/test_configuration/get_anomalies_test_configuration.sql)
[2024-03-29T00:01:36.913+0000] {subprocess.py:93} INFO -   > called by macro test_table_anomalies (macros/edr/tests/test_table_anomalies.sql)
[2024-03-29T00:01:36.914+0000] {subprocess.py:93} INFO -   > called by macro test_freshness_anomalies (macros/edr/tests/test_freshness_anomalies.sql)
[2024-03-29T00:01:36.914+0000] {subprocess.py:93} INFO -   > called by test elementary_freshness_anomalies_raw_orders_minute__1__creation_date (models/example/schema.yml)
[2024-03-29T00:01:36.915+0000] {subprocess.py:93} INFO - [0m00:01:36
[2024-03-29T00:01:36.916+0000] {subprocess.py:93} INFO - [0m00:01:36  Done. PASS=4 WARN=0 ERROR=1 SKIP=0 TOTAL=5
[2024-03-29T00:01:38.196+0000] {subprocess.py:97} INFO - Command exited with return code 1
[2024-03-29T00:01:38.218+0000] {taskinstance.py:2698} ERROR - Task failed with exception
Traceback (most recent call last):
  File "/home/airflow/.local/lib/python3.8/site-packages/airflow/models/taskinstance.py", line 433, in _execute_task
    result = execute_callable(context=context, **execute_callable_kwargs)
  File "/home/airflow/.local/lib/python3.8/site-packages/airflow/operators/bash.py", line 212, in execute
    raise AirflowException(
airflow.exceptions.AirflowException: Bash command failed. The command returned a non-zero exit code 1.
[2024-03-29T00:01:38.295+0000] {taskinstance.py:1138} INFO - Marking task as UP_FOR_RETRY. dag_id=dag___dbt, task_id=dbt_data_quality_checks, execution_date=20240328T000000, start_date=20240329T000105, end_date=20240329T000138
[2024-03-29T00:01:38.330+0000] {standard_task_runner.py:107} ERROR - Failed to execute job 68 for task dbt_data_quality_checks (Bash command failed. The command returned a non-zero exit code 1.; 16875)
[2024-03-29T00:01:38.374+0000] {local_task_job_runner.py:234} INFO - Task exited with return code 1
[2024-03-29T00:01:38.417+0000] {taskinstance.py:3280} INFO - 0 downstream tasks scheduled from follow-on schedule check
