[2024-03-29T00:06:41.126+0000] {taskinstance.py:1956} INFO - Dependencies all met for dep_context=non-requeueable deps ti=<TaskInstance: dag___dbt.dbt_data_quality_checks scheduled__2024-03-28T00:00:00+00:00 [queued]>
[2024-03-29T00:06:41.138+0000] {taskinstance.py:1956} INFO - Dependencies all met for dep_context=requeueable deps ti=<TaskInstance: dag___dbt.dbt_data_quality_checks scheduled__2024-03-28T00:00:00+00:00 [queued]>
[2024-03-29T00:06:41.139+0000] {taskinstance.py:2170} INFO - Starting attempt 2 of 2
[2024-03-29T00:06:41.160+0000] {taskinstance.py:2191} INFO - Executing <Task(BashOperator): dbt_data_quality_checks> on 2024-03-28 00:00:00+00:00
[2024-03-29T00:06:41.167+0000] {standard_task_runner.py:60} INFO - Started process 16965 to run task
[2024-03-29T00:06:41.171+0000] {standard_task_runner.py:87} INFO - Running: ['***', 'tasks', 'run', 'dag___dbt', 'dbt_data_quality_checks', 'scheduled__2024-03-28T00:00:00+00:00', '--job-id', '69', '--raw', '--subdir', 'DAGS_FOLDER/dbt_dag.py', '--cfg-path', '/tmp/tmpv2j3fv6v']
[2024-03-29T00:06:41.175+0000] {standard_task_runner.py:88} INFO - Job 69: Subtask dbt_data_quality_checks
[2024-03-29T00:06:41.237+0000] {task_command.py:423} INFO - Running <TaskInstance: dag___dbt.dbt_data_quality_checks scheduled__2024-03-28T00:00:00+00:00 [running]> on host 62dc842f1ceb
[2024-03-29T00:06:41.344+0000] {taskinstance.py:2480} INFO - Exporting env vars: AIRFLOW_CTX_DAG_OWNER='***' AIRFLOW_CTX_DAG_ID='dag___dbt' AIRFLOW_CTX_TASK_ID='dbt_data_quality_checks' AIRFLOW_CTX_EXECUTION_DATE='2024-03-28T00:00:00+00:00' AIRFLOW_CTX_TRY_NUMBER='2' AIRFLOW_CTX_DAG_RUN_ID='scheduled__2024-03-28T00:00:00+00:00'
[2024-03-29T00:06:41.348+0000] {subprocess.py:63} INFO - Tmp dir root location: /tmp
[2024-03-29T00:06:41.349+0000] {subprocess.py:75} INFO - Running command: ['/usr/bin/bash', '-c', '/home/***/.local/bin/dbt test --profiles-dir /home/***/.dbt --project-dir /opt/***/proj']
[2024-03-29T00:06:41.365+0000] {subprocess.py:86} INFO - Output:
[2024-03-29T00:06:45.593+0000] {subprocess.py:93} INFO - [0m00:06:45  Running with dbt=1.7.10
[2024-03-29T00:06:46.063+0000] {subprocess.py:93} INFO - [0m00:06:46  Registered adapter: postgres=1.7.10
[2024-03-29T00:07:06.175+0000] {subprocess.py:93} INFO - [0m00:07:06  Found 34 models, 2 operations, 5 tests, 1 source, 0 exposures, 0 metrics, 1407 macros, 0 groups, 0 semantic models
[2024-03-29T00:07:06.185+0000] {subprocess.py:93} INFO - [0m00:07:06
[2024-03-29T00:07:06.889+0000] {subprocess.py:93} INFO - [0m00:07:06
[2024-03-29T00:07:06.892+0000] {subprocess.py:93} INFO - [0m00:07:06  Running 1 on-run-start hook
[2024-03-29T00:07:07.078+0000] {subprocess.py:93} INFO - [0m00:07:07  1 of 1 START hook: elementary.on-run-start.0 ................................... [RUN]
[2024-03-29T00:07:07.080+0000] {subprocess.py:93} INFO - [0m00:07:07  1 of 1 OK hook: elementary.on-run-start.0 ...................................... [[32mOK[0m in 0.00s]
[2024-03-29T00:07:07.082+0000] {subprocess.py:93} INFO - [0m00:07:07
[2024-03-29T00:07:07.087+0000] {subprocess.py:93} INFO - [0m00:07:07  Concurrency: 1 threads (target='dev')
[2024-03-29T00:07:07.090+0000] {subprocess.py:93} INFO - [0m00:07:07
[2024-03-29T00:07:07.107+0000] {subprocess.py:93} INFO - [0m00:07:07  1 of 5 START test elementary_freshness_anomalies_raw_orders_minute__1__creation_date  [RUN]
[2024-03-29T00:07:07.489+0000] {subprocess.py:93} INFO - [0m00:07:07  1 of 5 ERROR elementary_freshness_anomalies_raw_orders_minute__1__creation_date  [[31mERROR[0m in 0.38s]
[2024-03-29T00:07:07.496+0000] {subprocess.py:93} INFO - [0m00:07:07  2 of 5 START test not_null_my_second_dbt_model_id .............................. [RUN]
[2024-03-29T00:07:08.446+0000] {subprocess.py:93} INFO - [0m00:07:08  2 of 5 PASS not_null_my_second_dbt_model_id .................................... [[32mPASS[0m in 0.95s]
[2024-03-29T00:07:08.457+0000] {subprocess.py:93} INFO - [0m00:07:08  3 of 5 START test not_null_raw_orders_creation_date ............................ [RUN]
[2024-03-29T00:07:08.731+0000] {subprocess.py:93} INFO - [0m00:07:08  3 of 5 PASS not_null_raw_orders_creation_date .................................. [[32mPASS[0m in 0.27s]
[2024-03-29T00:07:08.741+0000] {subprocess.py:93} INFO - [0m00:07:08  4 of 5 START test unique_my_first_dbt_model_id ................................. [RUN]
[2024-03-29T00:07:09.104+0000] {subprocess.py:93} INFO - [0m00:07:09  4 of 5 PASS unique_my_first_dbt_model_id ....................................... [[32mPASS[0m in 0.36s]
[2024-03-29T00:07:09.115+0000] {subprocess.py:93} INFO - [0m00:07:09  5 of 5 START test unique_my_second_dbt_model_id ................................ [RUN]
[2024-03-29T00:07:09.390+0000] {subprocess.py:93} INFO - [0m00:07:09  5 of 5 PASS unique_my_second_dbt_model_id ...................................... [[32mPASS[0m in 0.27s]
[2024-03-29T00:07:09.515+0000] {subprocess.py:93} INFO - [0m00:07:09
[2024-03-29T00:07:09.517+0000] {subprocess.py:93} INFO - [0m00:07:09  Running 1 on-run-end hook
[2024-03-29T00:07:13.848+0000] {subprocess.py:93} INFO - [0m00:07:13  1 of 1 START hook: elementary.on-run-end.0 ..................................... [RUN]
[2024-03-29T00:07:13.851+0000] {subprocess.py:93} INFO - [0m00:07:13  1 of 1 OK hook: elementary.on-run-end.0 ........................................ [[32mOK[0m in 0.00s]
[2024-03-29T00:07:13.854+0000] {subprocess.py:93} INFO - [0m00:07:13
[2024-03-29T00:07:13.865+0000] {subprocess.py:93} INFO - [0m00:07:13
[2024-03-29T00:07:13.867+0000] {subprocess.py:93} INFO - [0m00:07:13  Finished running 5 tests, 2 hooks in 0 hours 0 minutes and 7.68 seconds (7.68s).
[2024-03-29T00:07:14.002+0000] {subprocess.py:93} INFO - [0m00:07:14
[2024-03-29T00:07:14.004+0000] {subprocess.py:93} INFO - [0m00:07:14  [31mCompleted with 1 error and 0 warnings:[0m
[2024-03-29T00:07:14.006+0000] {subprocess.py:93} INFO - [0m00:07:14
[2024-03-29T00:07:14.008+0000] {subprocess.py:93} INFO - [0m00:07:14    Compilation Error in test elementary_freshness_anomalies_raw_orders_minute__1__creation_date (models/example/schema.yml)
[2024-03-29T00:07:14.009+0000] {subprocess.py:93} INFO -   time_bucket.period value should be one of ['hour', 'day', 'week', 'month'], got: minute
[2024-03-29T00:07:14.010+0000] {subprocess.py:93} INFO - 
[2024-03-29T00:07:14.010+0000] {subprocess.py:93} INFO -   > in macro validate_time_bucket (macros/edr/tests/test_configuration/get_time_bucket.sql)
[2024-03-29T00:07:14.011+0000] {subprocess.py:93} INFO -   > called by macro get_time_bucket (macros/edr/tests/test_configuration/get_time_bucket.sql)
[2024-03-29T00:07:14.012+0000] {subprocess.py:93} INFO -   > called by macro get_anomalies_test_configuration (macros/edr/tests/test_configuration/get_anomalies_test_configuration.sql)
[2024-03-29T00:07:14.012+0000] {subprocess.py:93} INFO -   > called by macro test_table_anomalies (macros/edr/tests/test_table_anomalies.sql)
[2024-03-29T00:07:14.013+0000] {subprocess.py:93} INFO -   > called by macro test_freshness_anomalies (macros/edr/tests/test_freshness_anomalies.sql)
[2024-03-29T00:07:14.014+0000] {subprocess.py:93} INFO -   > called by test elementary_freshness_anomalies_raw_orders_minute__1__creation_date (models/example/schema.yml)
[2024-03-29T00:07:14.014+0000] {subprocess.py:93} INFO - [0m00:07:14
[2024-03-29T00:07:14.015+0000] {subprocess.py:93} INFO - [0m00:07:14  Done. PASS=4 WARN=0 ERROR=1 SKIP=0 TOTAL=5
[2024-03-29T00:07:15.360+0000] {subprocess.py:97} INFO - Command exited with return code 1
[2024-03-29T00:07:15.379+0000] {taskinstance.py:2698} ERROR - Task failed with exception
Traceback (most recent call last):
  File "/home/airflow/.local/lib/python3.8/site-packages/airflow/models/taskinstance.py", line 433, in _execute_task
    result = execute_callable(context=context, **execute_callable_kwargs)
  File "/home/airflow/.local/lib/python3.8/site-packages/airflow/operators/bash.py", line 212, in execute
    raise AirflowException(
airflow.exceptions.AirflowException: Bash command failed. The command returned a non-zero exit code 1.
[2024-03-29T00:07:15.385+0000] {taskinstance.py:1138} INFO - Marking task as FAILED. dag_id=dag___dbt, task_id=dbt_data_quality_checks, execution_date=20240328T000000, start_date=20240329T000641, end_date=20240329T000715
[2024-03-29T00:07:15.406+0000] {standard_task_runner.py:107} ERROR - Failed to execute job 69 for task dbt_data_quality_checks (Bash command failed. The command returned a non-zero exit code 1.; 16965)
[2024-03-29T00:07:15.430+0000] {local_task_job_runner.py:234} INFO - Task exited with return code 1
[2024-03-29T00:07:15.463+0000] {taskinstance.py:3280} INFO - 0 downstream tasks scheduled from follow-on schedule check
