[2024-04-01T09:44:35.341+0000] {taskinstance.py:1956} INFO - Dependencies all met for dep_context=non-requeueable deps ti=<TaskInstance: dag___dbt.run_model1 scheduled__2024-04-01T07:00:00+00:00 [queued]>
[2024-04-01T09:44:35.411+0000] {taskinstance.py:1956} INFO - Dependencies all met for dep_context=requeueable deps ti=<TaskInstance: dag___dbt.run_model1 scheduled__2024-04-01T07:00:00+00:00 [queued]>
[2024-04-01T09:44:35.417+0000] {taskinstance.py:2170} INFO - Starting attempt 1 of 2
[2024-04-01T09:44:35.524+0000] {taskinstance.py:2191} INFO - Executing <Task(BashOperator): run_model1> on 2024-04-01 07:00:00+00:00
[2024-04-01T09:44:35.594+0000] {standard_task_runner.py:60} INFO - Started process 133 to run task
[2024-04-01T09:44:35.601+0000] {standard_task_runner.py:87} INFO - Running: ['***', 'tasks', 'run', 'dag___dbt', 'run_model1', 'scheduled__2024-04-01T07:00:00+00:00', '--job-id', '83', '--raw', '--subdir', 'DAGS_FOLDER/freshness_test_dag.py', '--cfg-path', '/tmp/tmp6_d4x5id']
[2024-04-01T09:44:35.613+0000] {standard_task_runner.py:88} INFO - Job 83: Subtask run_model1
[2024-04-01T09:44:36.030+0000] {task_command.py:423} INFO - Running <TaskInstance: dag___dbt.run_model1 scheduled__2024-04-01T07:00:00+00:00 [running]> on host 62dc842f1ceb
[2024-04-01T09:44:36.710+0000] {taskinstance.py:2480} INFO - Exporting env vars: AIRFLOW_CTX_DAG_OWNER='***' AIRFLOW_CTX_DAG_ID='dag___dbt' AIRFLOW_CTX_TASK_ID='run_model1' AIRFLOW_CTX_EXECUTION_DATE='2024-04-01T07:00:00+00:00' AIRFLOW_CTX_TRY_NUMBER='1' AIRFLOW_CTX_DAG_RUN_ID='scheduled__2024-04-01T07:00:00+00:00'
[2024-04-01T09:44:36.739+0000] {subprocess.py:63} INFO - Tmp dir root location: /tmp
[2024-04-01T09:44:36.771+0000] {subprocess.py:75} INFO - Running command: ['/usr/bin/bash', '-c', '/home/***/.local/bin/dbt run --models my_first_dbt_model my_second_dbt_model  --profiles-dir /home/***/.dbt --project-dir /opt/***/proj']
[2024-04-01T09:44:36.862+0000] {subprocess.py:86} INFO - Output:
[2024-04-01T09:45:07.592+0000] {subprocess.py:93} INFO - [0m09:45:07  Running with dbt=1.7.10
[2024-04-01T09:45:11.760+0000] {subprocess.py:93} INFO - [0m09:45:11  Registered adapter: postgres=1.7.10
[2024-04-01T09:45:36.134+0000] {subprocess.py:93} INFO - [0m09:45:29  Encountered an error:
[2024-04-01T09:45:41.686+0000] {subprocess.py:93} INFO - [Errno 5] Input/output error: '/opt/***/proj/dbt_packages/dbt_expectations/macros/schema_tests/aggregate_functions/expect_column_distinct_count_to_be_greater_than.sql'
[2024-04-01T09:45:41.738+0000] {subprocess.py:93} INFO - [0m09:45:41  Traceback (most recent call last):
[2024-04-01T09:45:41.740+0000] {subprocess.py:93} INFO -   File "/home/***/.local/lib/python3.8/site-packages/dbt/cli/requires.py", line 91, in wrapper
[2024-04-01T09:45:41.741+0000] {subprocess.py:93} INFO -     result, success = func(*args, **kwargs)
[2024-04-01T09:45:41.752+0000] {subprocess.py:93} INFO -   File "/home/***/.local/lib/python3.8/site-packages/dbt/cli/requires.py", line 76, in wrapper
[2024-04-01T09:45:41.753+0000] {subprocess.py:93} INFO -     return func(*args, **kwargs)
[2024-04-01T09:45:41.754+0000] {subprocess.py:93} INFO -   File "/home/***/.local/lib/python3.8/site-packages/dbt/cli/requires.py", line 169, in wrapper
[2024-04-01T09:45:41.759+0000] {subprocess.py:93} INFO -     return func(*args, **kwargs)
[2024-04-01T09:45:41.865+0000] {subprocess.py:93} INFO -   File "/home/***/.local/lib/python3.8/site-packages/dbt/cli/requires.py", line 198, in wrapper
[2024-04-01T09:45:41.878+0000] {subprocess.py:93} INFO -     return func(*args, **kwargs)
[2024-04-01T09:45:41.881+0000] {subprocess.py:93} INFO -   File "/home/***/.local/lib/python3.8/site-packages/dbt/cli/requires.py", line 245, in wrapper
[2024-04-01T09:45:41.884+0000] {subprocess.py:93} INFO -     return func(*args, **kwargs)
[2024-04-01T09:45:41.886+0000] {subprocess.py:93} INFO -   File "/home/***/.local/lib/python3.8/site-packages/dbt/cli/requires.py", line 271, in wrapper
[2024-04-01T09:45:41.888+0000] {subprocess.py:93} INFO -     ctx.obj["manifest"] = parse_manifest(
[2024-04-01T09:45:41.889+0000] {subprocess.py:93} INFO -   File "/home/***/.local/lib/python3.8/site-packages/dbt/parser/manifest.py", line 1798, in parse_manifest
[2024-04-01T09:45:41.890+0000] {subprocess.py:93} INFO -     manifest = ManifestLoader.get_full_manifest(
[2024-04-01T09:45:41.892+0000] {subprocess.py:93} INFO -   File "/home/***/.local/lib/python3.8/site-packages/dbt/parser/manifest.py", line 318, in get_full_manifest
[2024-04-01T09:45:41.894+0000] {subprocess.py:93} INFO -     manifest = loader.load()
[2024-04-01T09:45:41.895+0000] {subprocess.py:93} INFO -   File "/home/***/.local/lib/python3.8/site-packages/dbt/parser/manifest.py", line 365, in load
[2024-04-01T09:45:41.897+0000] {subprocess.py:93} INFO -     file_reader.read_files()
[2024-04-01T09:45:41.898+0000] {subprocess.py:93} INFO -   File "/home/***/.local/lib/python3.8/site-packages/dbt/parser/read_files.py", line 203, in read_files
[2024-04-01T09:45:41.900+0000] {subprocess.py:93} INFO -     self.read_files_for_project(project, file_types)
[2024-04-01T09:45:41.902+0000] {subprocess.py:93} INFO -   File "/home/***/.local/lib/python3.8/site-packages/dbt/parser/read_files.py", line 210, in read_files_for_project
[2024-04-01T09:45:41.903+0000] {subprocess.py:93} INFO -     project_files[file_type_info["parser"]] = read_files_for_parser(
[2024-04-01T09:45:41.905+0000] {subprocess.py:93} INFO -   File "/home/***/.local/lib/python3.8/site-packages/dbt/parser/read_files.py", line 158, in read_files_for_parser
[2024-04-01T09:45:41.910+0000] {subprocess.py:93} INFO -     source_files = get_source_files(
[2024-04-01T09:45:41.911+0000] {subprocess.py:93} INFO -   File "/home/***/.local/lib/python3.8/site-packages/dbt/parser/read_files.py", line 134, in get_source_files
[2024-04-01T09:45:41.913+0000] {subprocess.py:93} INFO -     fp_list = filesystem_search(project, paths, extension, ignore_spec)
[2024-04-01T09:45:41.917+0000] {subprocess.py:93} INFO -   File "/home/***/.local/lib/python3.8/site-packages/dbt/parser/search.py", line 74, in filesystem_search
[2024-04-01T09:45:41.920+0000] {subprocess.py:93} INFO -     for result in find_matching(root, relative_dirs, ext, ignore_spec):
[2024-04-01T09:45:41.936+0000] {subprocess.py:93} INFO -   File "/home/***/.local/lib/python3.8/site-packages/dbt/clients/system.py", line 79, in find_matching
[2024-04-01T09:45:41.941+0000] {subprocess.py:93} INFO -     modification_time = os.path.getmtime(absolute_path)
[2024-04-01T09:45:41.946+0000] {subprocess.py:93} INFO -   File "/usr/local/lib/python3.8/genericpath.py", line 55, in getmtime
[2024-04-01T09:45:41.949+0000] {subprocess.py:93} INFO -     return os.stat(filename).st_mtime
[2024-04-01T09:45:41.954+0000] {subprocess.py:93} INFO - OSError: [Errno 5] Input/output error: '/opt/***/proj/dbt_packages/dbt_expectations/macros/schema_tests/aggregate_functions/expect_column_distinct_count_to_be_greater_than.sql'
[2024-04-01T09:45:41.968+0000] {subprocess.py:93} INFO - 
[2024-04-01T09:45:41.639+0000] {job.py:213} ERROR - Job heartbeat got an exception
Traceback (most recent call last):
  File "/home/airflow/.local/lib/python3.8/site-packages/sqlalchemy/engine/base.py", line 3371, in _wrap_pool_connect
    return fn()
  File "/home/airflow/.local/lib/python3.8/site-packages/sqlalchemy/pool/base.py", line 327, in connect
    return _ConnectionFairy._checkout(self)
  File "/home/airflow/.local/lib/python3.8/site-packages/sqlalchemy/pool/base.py", line 894, in _checkout
    fairy = _ConnectionRecord.checkout(pool)
  File "/home/airflow/.local/lib/python3.8/site-packages/sqlalchemy/pool/base.py", line 493, in checkout
    rec = pool._do_get()
  File "/home/airflow/.local/lib/python3.8/site-packages/sqlalchemy/pool/impl.py", line 256, in _do_get
    return self._create_connection()
  File "/home/airflow/.local/lib/python3.8/site-packages/sqlalchemy/pool/base.py", line 273, in _create_connection
    return _ConnectionRecord(self)
  File "/home/airflow/.local/lib/python3.8/site-packages/sqlalchemy/pool/base.py", line 388, in __init__
    self.__connect()
  File "/home/airflow/.local/lib/python3.8/site-packages/sqlalchemy/pool/base.py", line 691, in __connect
    pool.logger.debug("Error on connect(): %s", e)
  File "/home/airflow/.local/lib/python3.8/site-packages/sqlalchemy/util/langhelpers.py", line 70, in __exit__
    compat.raise_(
  File "/home/airflow/.local/lib/python3.8/site-packages/sqlalchemy/util/compat.py", line 211, in raise_
    raise exception
  File "/home/airflow/.local/lib/python3.8/site-packages/sqlalchemy/pool/base.py", line 686, in __connect
    self.dbapi_connection = connection = pool._invoke_creator(self)
  File "/home/airflow/.local/lib/python3.8/site-packages/sqlalchemy/engine/create.py", line 574, in connect
    return dialect.connect(*cargs, **cparams)
  File "/home/airflow/.local/lib/python3.8/site-packages/sqlalchemy/engine/default.py", line 598, in connect
    return self.dbapi.connect(*cargs, **cparams)
  File "/home/airflow/.local/lib/python3.8/site-packages/psycopg2/__init__.py", line 122, in connect
    conn = _connect(dsn, connection_factory=connection_factory, **kwasync)
psycopg2.OperationalError: could not translate host name "postgres" to address: Temporary failure in name resolution


The above exception was the direct cause of the following exception:

Traceback (most recent call last):
  File "/home/airflow/.local/lib/python3.8/site-packages/airflow/jobs/job.py", line 187, in heartbeat
    self._merge_from(Job._fetch_from_db(self, session))
  File "/home/airflow/.local/lib/python3.8/site-packages/airflow/api_internal/internal_api_call.py", line 114, in wrapper
    return func(*args, **kwargs)
  File "/home/airflow/.local/lib/python3.8/site-packages/airflow/utils/session.py", line 76, in wrapper
    return func(*args, **kwargs)
  File "/home/airflow/.local/lib/python3.8/site-packages/airflow/jobs/job.py", line 308, in _fetch_from_db
    session.merge(job)
  File "/home/airflow/.local/lib/python3.8/site-packages/sqlalchemy/orm/session.py", line 3056, in merge
    return self._merge(
  File "/home/airflow/.local/lib/python3.8/site-packages/sqlalchemy/orm/session.py", line 3136, in _merge
    merged = self.get(
  File "/home/airflow/.local/lib/python3.8/site-packages/sqlalchemy/orm/session.py", line 2853, in get
    return self._get_impl(
  File "/home/airflow/.local/lib/python3.8/site-packages/sqlalchemy/orm/session.py", line 2975, in _get_impl
    return db_load_fn(
  File "/home/airflow/.local/lib/python3.8/site-packages/sqlalchemy/orm/loading.py", line 530, in load_on_pk_identity
    session.execute(
  File "/home/airflow/.local/lib/python3.8/site-packages/sqlalchemy/orm/session.py", line 1716, in execute
    conn = self._connection_for_bind(bind)
  File "/home/airflow/.local/lib/python3.8/site-packages/sqlalchemy/orm/session.py", line 1555, in _connection_for_bind
    return self._transaction._connection_for_bind(
  File "/home/airflow/.local/lib/python3.8/site-packages/sqlalchemy/orm/session.py", line 750, in _connection_for_bind
    conn = bind.connect()
  File "/home/airflow/.local/lib/python3.8/site-packages/sqlalchemy/future/engine.py", line 412, in connect
    return super(Engine, self).connect()
  File "/home/airflow/.local/lib/python3.8/site-packages/sqlalchemy/engine/base.py", line 3325, in connect
    return self._connection_cls(self, close_with_result=close_with_result)
  File "/home/airflow/.local/lib/python3.8/site-packages/sqlalchemy/engine/base.py", line 96, in __init__
    else engine.raw_connection()
  File "/home/airflow/.local/lib/python3.8/site-packages/sqlalchemy/engine/base.py", line 3404, in raw_connection
    return self._wrap_pool_connect(self.pool.connect, _connection)
  File "/home/airflow/.local/lib/python3.8/site-packages/sqlalchemy/engine/base.py", line 3374, in _wrap_pool_connect
    Connection._handle_dbapi_exception_noconnection(
  File "/home/airflow/.local/lib/python3.8/site-packages/sqlalchemy/engine/base.py", line 2208, in _handle_dbapi_exception_noconnection
    util.raise_(
  File "/home/airflow/.local/lib/python3.8/site-packages/sqlalchemy/util/compat.py", line 211, in raise_
    raise exception
  File "/home/airflow/.local/lib/python3.8/site-packages/sqlalchemy/engine/base.py", line 3371, in _wrap_pool_connect
    return fn()
  File "/home/airflow/.local/lib/python3.8/site-packages/sqlalchemy/pool/base.py", line 327, in connect
    return _ConnectionFairy._checkout(self)
  File "/home/airflow/.local/lib/python3.8/site-packages/sqlalchemy/pool/base.py", line 894, in _checkout
    fairy = _ConnectionRecord.checkout(pool)
  File "/home/airflow/.local/lib/python3.8/site-packages/sqlalchemy/pool/base.py", line 493, in checkout
    rec = pool._do_get()
  File "/home/airflow/.local/lib/python3.8/site-packages/sqlalchemy/pool/impl.py", line 256, in _do_get
    return self._create_connection()
  File "/home/airflow/.local/lib/python3.8/site-packages/sqlalchemy/pool/base.py", line 273, in _create_connection
    return _ConnectionRecord(self)
  File "/home/airflow/.local/lib/python3.8/site-packages/sqlalchemy/pool/base.py", line 388, in __init__
    self.__connect()
  File "/home/airflow/.local/lib/python3.8/site-packages/sqlalchemy/pool/base.py", line 691, in __connect
    pool.logger.debug("Error on connect(): %s", e)
  File "/home/airflow/.local/lib/python3.8/site-packages/sqlalchemy/util/langhelpers.py", line 70, in __exit__
    compat.raise_(
  File "/home/airflow/.local/lib/python3.8/site-packages/sqlalchemy/util/compat.py", line 211, in raise_
    raise exception
  File "/home/airflow/.local/lib/python3.8/site-packages/sqlalchemy/pool/base.py", line 686, in __connect
    self.dbapi_connection = connection = pool._invoke_creator(self)
  File "/home/airflow/.local/lib/python3.8/site-packages/sqlalchemy/engine/create.py", line 574, in connect
    return dialect.connect(*cargs, **cparams)
  File "/home/airflow/.local/lib/python3.8/site-packages/sqlalchemy/engine/default.py", line 598, in connect
    return self.dbapi.connect(*cargs, **cparams)
  File "/home/airflow/.local/lib/python3.8/site-packages/psycopg2/__init__.py", line 122, in connect
    conn = _connect(dsn, connection_factory=connection_factory, **kwasync)
sqlalchemy.exc.OperationalError: (psycopg2.OperationalError) could not translate host name "postgres" to address: Temporary failure in name resolution

(Background on this error at: https://sqlalche.me/e/14/e3q8)
[2024-04-01T09:45:42.196+0000] {job.py:221} ERROR - Job heartbeat failed with error. Scheduler is in unhealthy state
[2024-04-01T09:45:58.693+0000] {job.py:221} ERROR - Job heartbeat failed with error. Scheduler is in unhealthy state
[2024-04-01T09:46:39.240+0000] {subprocess.py:97} INFO - Command exited with return code 2
[2024-04-01T09:46:40.289+0000] {taskinstance.py:2698} ERROR - Task failed with exception
Traceback (most recent call last):
  File "/home/airflow/.local/lib/python3.8/site-packages/airflow/models/taskinstance.py", line 433, in _execute_task
    result = execute_callable(context=context, **execute_callable_kwargs)
  File "/home/airflow/.local/lib/python3.8/site-packages/airflow/operators/bash.py", line 212, in execute
    raise AirflowException(
airflow.exceptions.AirflowException: Bash command failed. The command returned a non-zero exit code 2.
[2024-04-01T09:46:40.425+0000] {taskinstance.py:1138} INFO - Marking task as UP_FOR_RETRY. dag_id=dag___dbt, task_id=run_model1, execution_date=20240401T070000, start_date=20240401T094435, end_date=20240401T094640
[2024-04-01T09:46:40.714+0000] {standard_task_runner.py:107} ERROR - Failed to execute job 83 for task run_model1 (Bash command failed. The command returned a non-zero exit code 2.; 133)
[2024-04-01T09:46:40.826+0000] {local_task_job_runner.py:234} INFO - Task exited with return code 1
[2024-04-01T09:46:41.056+0000] {taskinstance.py:3280} INFO - 0 downstream tasks scheduled from follow-on schedule check
